Workbook

Sheet Dashboard
A1: AI-Powered Smart Municipal Citizen Assistance & Staff Attendance Management System - Executive Dashboard
A2: Overall Completion % | C2: Blocked Tasks | E2: Critical Issues Open | G2: Open Bugs | I2: Security Checklist % | K2: Deployment Readiness %
A3: ==COUNTIF(F16:F72, "Completed")/COUNTA(A16:A72) -> 0.33333333 | C3: ==COUNTIF(F16:F72, "Blocked") -> 0 | E3: ==COUNTIFS(E16:E72, "Critical", F16:F72, "<>Completed") -> 2 | G3: ==COUNTIFS('Bug Tracker'!G3:G30, "<>Completed", 'Bug Tracker'!G3:G30, "<>") -> 1 | I3: ==COUNTIF('Security Checklist'!D3:D14, "Completed")/COUNTA('Security Checklist'!D3:D14) -> 0.25 | K3: ==COUNTIF('Deployment Checklist'!D3:D10, "Completed")/COUNTA('Deployment Checklist'!D3:D10) -> 0.375
A6: Team Workload & Progress Summary | H6: Module Development Status | O6: Day-Wise Progress Timeline
A7: Team Member | B7: Assigned Tasks | C7: Completed | D7: Pending | E7: Blocked | F7: Completion % | H7: Module Name | I7: Total Tasks | J7: Completed | K7: Pending | L7: Blocked | M7: Completion % | O7: Day | P7: Total Tasks | Q7: Completed | R7: Completion %
A8: Minha Palakkathodi | B8: ==COUNTIF($D$16:$D$72, A8) -> 6 | C8: ==COUNTIFS($D$16:$D$72, A8, $F$16:$F$72, "Completed") -> 2 | D8: ==B8-C8-E8 -> 4 | E8: ==COUNTIFS($D$16:$D$72, A8, $F$16:$F$72, "Blocked") -> 0 | F8: ==IF(B8>0, C8/B8, 0) -> 0.33333333 | H8: Backend | I8: ==COUNTIF($B$16:$B$72, H8) -> 11 | J8: ==COUNTIFS($B$16:$B$72, H8, $F$16:$F$72, "Completed") -> 3 | K8: ==I8-J8-L8 -> 8 | L8: ==COUNTIFS($B$16:$B$72, H8, $F$16:$F$72, "Blocked") -> 0 | M8: ==IF(I8>0, J8/I8, 0) -> 0.27272727 | O8: Sprint 0 | P8: ==COUNTIF($H$16:$H$72, O8) -> 5 | Q8: ==COUNTIFS($H$16:$H$72, O8, $F$16:$F$72, "Completed") -> 5 | R8: ==IF(P8>0, Q8/P8, 0) -> 1
A9: Adithyan N | B9: ==COUNTIF($D$16:$D$72, A9) -> 20 | C9: ==COUNTIFS($D$16:$D$72, A9, $F$16:$F$72, "Completed") -> 8 | D9: ==B9-C9-E9 -> 12 | E9: ==COUNTIFS($D$16:$D$72, A9, $F$16:$F$72, "Blocked") -> 0 | F9: ==IF(B9>0, C9/B9, 0) -> 0.4 | H9: Frontend | I9: ==COUNTIF($B$16:$B$72, H9) -> 18 | J9: ==COUNTIFS($B$16:$B$72, H9, $F$16:$F$72, "Completed") -> 7 | K9: ==I9-J9-L9 -> 11 | L9: ==COUNTIFS($B$16:$B$72, H9, $F$16:$F$72, "Blocked") -> 0 | M9: ==IF(I9>0, J9/I9, 0) -> 0.38888889 | O9: Day 1 | P9: ==COUNTIF($H$16:$H$72, O9) -> 7 | Q9: ==COUNTIFS($H$16:$H$72, O9, $F$16:$F$72, "Completed") -> 7 | R9: ==IF(P9>0, Q9/P9, 0) -> 1
A10: Fathima Hana | B10: ==COUNTIF($D$16:$D$72, A10) -> 6 | C10: ==COUNTIFS($D$16:$D$72, A10, $F$16:$F$72, "Completed") -> 4 | D10: ==B10-C10-E10 -> 2 | E10: ==COUNTIFS($D$16:$D$72, A10, $F$16:$F$72, "Blocked") -> 0 | F10: ==IF(B10>0, C10/B10, 0) -> 0.66666667 | H10: Database | I10: ==COUNTIF($B$16:$B$72, H10) -> 6 | J10: ==COUNTIFS($B$16:$B$72, H10, $F$16:$F$72, "Completed") -> 4 | K10: ==I10-J10-L10 -> 2 | L10: ==COUNTIFS($B$16:$B$72, H10, $F$16:$F$72, "Blocked") -> 0 | M10: ==IF(I10>0, J10/I10, 0) -> 0.66666667 | O10: Day 2 | P10: ==COUNTIF($H$16:$H$72, O10) -> 5 | Q10: ==COUNTIFS($H$16:$H$72, O10, $F$16:$F$72, "Completed") -> 5 | R10: ==IF(P10>0, Q10/P10, 0) -> 1
A11: Muhammad Sanish | B11: ==COUNTIF($D$16:$D$72, A11) -> 13 | C11: ==COUNTIFS($D$16:$D$72, A11, $F$16:$F$72, "Completed") -> 5 | D11: ==B11-C11-E11 -> 8 | E11: ==COUNTIFS($D$16:$D$72, A11, $F$16:$F$72, "Blocked") -> 0 | F11: ==IF(B11>0, C11/B11, 0) -> 0.38461538 | H11: AI | I11: ==COUNTIF($B$16:$B$72, H11) -> 5 | J11: ==COUNTIFS($B$16:$B$72, H11, $F$16:$F$72, "Completed") -> 0 | K11: ==I11-J11-L11 -> 5 | L11: ==COUNTIFS($B$16:$B$72, H11, $F$16:$F$72, "Blocked") -> 0 | M11: ==IF(I11>0, J11/I11, 0) -> 0 | O11: Day 3 | P11: ==COUNTIF($H$16:$H$72, O11) -> 6 | Q11: ==COUNTIFS($H$16:$H$72, O11, $F$16:$F$72, "Completed") -> 2 | R11: ==IF(P11>0, Q11/P11, 0) -> 0.33333333
A12: Fadi Ahmed | B12: ==COUNTIF($D$16:$D$72, A12) -> 7 | C12: ==COUNTIFS($D$16:$D$72, A12, $F$16:$F$72, "Completed") -> 0 | D12: ==B12-C12-E12 -> 7 | E12: ==COUNTIFS($D$16:$D$72, A12, $F$16:$F$72, "Blocked") -> 0 | F12: ==IF(B12>0, C12/B12, 0) -> 0 | H12: Face Recognition | I12: ==COUNTIF($B$16:$B$72, H12) -> 7 | J12: ==COUNTIFS($B$16:$B$72, H12, $F$16:$F$72, "Completed") -> 0 | K12: ==I12-J12-L12 -> 7 | L12: ==COUNTIFS($B$16:$B$72, H12, $F$16:$F$72, "Blocked") -> 0 | M12: ==IF(I12>0, J12/I12, 0) -> 0 | O12: Day 4 | P12: ==COUNTIF($H$16:$H$72, O12) -> 7 | Q12: ==COUNTIFS($H$16:$H$72, O12, $F$16:$F$72, "Completed") -> 0 | R12: ==IF(P12>0, Q12/P12, 0) -> 0
A13: Muhammed Sadik KT | B13: ==COUNTIF($D$16:$D$72, A13) -> 5 | C13: ==COUNTIFS($D$16:$D$72, A13, $F$16:$F$72, "Completed") -> 0 | D13: ==B13-C13-E13 -> 5 | E13: ==COUNTIFS($D$16:$D$72, A13, $F$16:$F$72, "Blocked") -> 0 | F13: ==IF(B13>0, C13/B13, 0) -> 0 | H13: Documentation & QA | I13: ==COUNTIF($B$16:$B$72, H13) -> 6 | J13: ==COUNTIFS($B$16:$B$72, H13, $F$16:$F$72, "Completed") -> 2 | K13: ==I13-J13-L13 -> 4 | L13: ==COUNTIFS($B$16:$B$72, H13, $F$16:$F$72, "Blocked") -> 0 | M13: ==IF(I13>0, J13/I13, 0) -> 0.33333333 | O13: Day 5 | P13: ==COUNTIF($H$16:$H$72, O13) -> 11 | Q13: ==COUNTIFS($H$16:$H$72, O13, $F$16:$F$72, "Completed") -> 0 | R13: ==IF(P13>0, Q13/P13, 0) -> 0
H14: Infrastructure | I14: ==COUNTIF($B$16:$B$72, H14) -> 4 | J14: ==COUNTIFS($B$16:$B$72, H14, $F$16:$F$72, "Completed") -> 3 | K14: ==I14-J14-L14 -> 1 | L14: ==COUNTIFS($B$16:$B$72, H14, $F$16:$F$72, "Blocked") -> 0 | M14: ==IF(I14>0, J14/I14, 0) -> 0.75 | O14: Day 6 | P14: ==COUNTIF($H$16:$H$72, O14) -> 11 | Q14: ==COUNTIFS($H$16:$H$72, O14, $F$16:$F$72, "Completed") -> 0 | R14: ==IF(P14>0, Q14/P14, 0) -> 0
A15: Task ID | B15: Module | C15: Task Name | D15: Assigned To | E15: Priority | F15: Status | G15: Progress % | H15: Due Day | I15: Dependency | J15: Testing Status | K15: Security Status | L15: Remarks | O15: Day 7 | P15: ==COUNTIF($H$16:$H$72, O15) -> 5 | Q15: ==COUNTIFS($H$16:$H$72, O15, $F$16:$F$72, "Completed") -> 0 | R15: ==IF(P15>0, Q15/P15, 0) -> 0
A16: TASK-INF-001 | B16: Infrastructure | C16: MongoDB Atlas Setup | D16: Adithyan N | E16: Critical | F16: Completed | G16: ==IF(F16="Completed", 1, IF(F16="In Progress", 0.5, IF(F16="Review", 0.8, 0))) -> 1 | H16: Sprint 0 | I16: None | J16: Completed | K16: Completed | L16: Admin controls configured and database connection verified
A17: TASK-INF-002 | B17: Infrastructure | C17: Environment Configuration | D17: Muhammad Sanish | E17: High | F17: Completed | G17: ==IF(F17="Completed", 1, IF(F17="In Progress", 0.5, IF(F17="Review", 0.8, 0))) -> 1 | H17: Sprint 0 | I17: None | J17: Completed | K17: Completed | L17: No secrets committed, configuration structure validated
A18: TASK-INF-003 | B18: Infrastructure | C18: Logging Infrastructure Setup | D18: Muhammad Sanish | E18: Medium | F18: Completed | G18: ==IF(F18="Completed", 1, IF(F18="In Progress", 0.5, IF(F18="Review", 0.8, 0))) -> 1 | H18: Day 1 | I18: TASK-INF-002 | J18: Completed | K18: Completed | L18: Sensitive data redacted in Winston streams
A19: TASK-INF-004 | B19: Infrastructure | C19: Deployment Environment Preparation | D19: Adithyan N | E19: Medium | F19: Not Started | G19: ==IF(F19="Completed", 1, IF(F19="In Progress", 0.5, IF(F19="Review", 0.8, 0))) -> 0 | H19: Day 7 | I19: None | J19: Pending | K19: Pending | L19: Deployment scripts drafted, hosting environments initialized
A20: TASK-FE-001 | B20: Frontend | C20: React Setup | D20: Adithyan N | E20: High | F20: Completed | G20: ==IF(F20="Completed", 1, IF(F20="In Progress", 0.5, IF(F20="Review", 0.8, 0))) -> 1 | H20: Sprint 0 | I20: None | J20: Completed | K20: Completed | L20: Vite React scaffolded with standard directory layout
A21: TASK-FE-002 | B21: Frontend | C21: Tailwind Setup | D21: Adithyan N | E21: High | F21: Completed | G21: ==IF(F21="Completed", 1, IF(F21="In Progress", 0.5, IF(F21="Review", 0.8, 0))) -> 1 | H21: Sprint 0 | I21: TASK-FE-001 | J21: Completed | K21: Completed | L21: Tailwind configuration, colors, and typography set up
A22: TASK-FE-003 | B22: Frontend | C22: Routing | D22: Adithyan N | E22: High | F22: Completed | G22: ==IF(F22="Completed", 1, IF(F22="In Progress", 0.5, IF(F22="Review", 0.8, 0))) -> 1 | H22: Day 1 | I22: TASK-FE-001 | J22: Completed | K22: Completed | L22: Browser router routes setup, layout routes configured
A23: TASK-FE-004 | B23: Frontend | C23: Protected Routes | D23: Adithyan N | E23: High | F23: Completed | G23: ==IF(F23="Completed", 1, IF(F23="In Progress", 0.5, IF(F23="Review", 0.8, 0))) -> 1 | H23: Day 1 | I23: TASK-FE-003 | J23: Completed | K23: Completed | L23: Client RBAC guard integrated with token decoder
A24: TASK-FE-005 | B24: Frontend | C24: Axios Setup | D24: Adithyan N | E24: High | F24: Completed | G24: ==IF(F24="Completed", 1, IF(F24="In Progress", 0.5, IF(F24="Review", 0.8, 0))) -> 1 | H24: Day 1 | I24: None | J24: Completed | K24: Completed | L24: JWT interceptor setup, retry limits configured
A25: TASK-FE-006 | B25: Frontend | C25: Authentication UI | D25: Adithyan N | E25: High | F25: Completed | G25: ==IF(F25="Completed", 1, IF(F25="In Progress", 0.5, IF(F25="Review", 0.8, 0))) -> 1 | H25: Day 2 | I25: TASK-FE-004 | J25: Completed | K25: Completed | L25: Secure cookie setup and form validations active
A26: TASK-FE-007 | B26: Frontend | C26: Citizen Dashboard | D26: Adithyan N | E26: High | F26: Completed | G26: ==IF(F26="Completed", 1, IF(F26="In Progress", 0.5, IF(F26="Review", 0.8, 0))) -> 1 | H26: Day 2 | I26: TASK-FE-004 | J26: Completed | K26: Completed | L26: Overview console with responsive metrics cards active
A27: TASK-FE-008 | B27: Frontend | C27: Complaint UI | D27: Adithyan N | E27: High | F27: In Progress | G27: ==IF(F27="Completed", 1, IF(F27="In Progress", 0.5, IF(F27="Review", 0.8, 0))) -> 0.5 | H27: Day 3 | I27: TASK-FE-007 | J27: Pending | K27: Pending | L27: Input sanitizations in progress, UI layout complete
... A72: TASK-QA-006 | B72: Documentation & QA | C72: Documentation Updates | D72: Minha Palakkathodi | E72: Medium | F72: Not Started | G72: ==IF(F72="Completed", 1, IF(F72="In Progress", 0.5, IF(F72="Review", 0.8, 0))) -> 0 | H72: Day 7 | I72: None | J72: Pending | K72: Pending | L72: Final directory inventory check template

Sheet Kanban Board
A1: AI-Powered Smart Municipal Kanban Board (Status Flow Tracker)
B3: Project Name: | C3: Smart Municipal Assistance MVP | E3: Enterprise Lead: | F3: Adithyan N & PMO Team | H3: Target Milestone: | I3: 1-Week Rapid MVP Release
A5: Backlog / Future | D5: Not Started | G5: In Progress | J5: Under Review | M5: Completed
A6: Task ID | B6: Task Name | C6: Assigned To | D6: Task ID | E6: Task Name | F6: Assigned To | G6: Task ID | H6: Task Name | I6: Assigned To | J6: Task ID | K6: Task Name | L6: Assigned To | M6: Task ID | N6: Task Name | O6: Assigned To
D7: ==Dashboard!A19 -> TASK-INF-004 | E7: ==Dashboard!C19 -> Deployment Environment Preparation | F7: ==Dashboard!D19 -> Adithyan N | G7: ==Dashboard!A27 -> TASK-FE-008 | H7: ==Dashboard!C27 -> Complaint UI | I7: ==Dashboard!D27 -> Adithyan N | J7: ==Dashboard!A41 -> TASK-BE-004 | K7: ==Dashboard!C41 -> Complaint APIs | L7: ==Dashboard!D41 -> Muhammad Sanish | M7: ==Dashboard!A16 -> TASK-INF-001 | N7: ==Dashboard!C16 -> MongoDB Atlas Setup | O7: ==Dashboard!D16 -> Adithyan N
D8: ==Dashboard!A29 -> TASK-FE-010 | E8: ==Dashboard!C29 -> Feedback UI | F8: ==Dashboard!D29 -> Adithyan N | G8: ==Dashboard!A28 -> TASK-FE-009 | H8: ==Dashboard!C28 -> File Tracking UI | I8: ==Dashboard!D28 -> Adithyan N | J8: ==Dashboard!A42 -> TASK-BE-005 | K8: ==Dashboard!C42 -> File Tracking APIs | L8: ==Dashboard!D42 -> Muhammad Sanish | M8: ==Dashboard!A17 -> TASK-INF-002 | N8: ==Dashboard!C17 -> Environment Configuration | O8: ==Dashboard!D17 -> Muhammad Sanish
D9: ==Dashboard!A30 -> TASK-FE-011 | E9: ==Dashboard!C30 -> Staff Dashboard UI | F9: ==Dashboard!D30 -> Adithyan N | M9: ==Dashboard!A18 -> TASK-INF-003 | N9: ==Dashboard!C18 -> Logging Infrastructure Setup | O9: ==Dashboard!D18 -> Muhammad Sanish
D10: ==Dashboard!A31 -> TASK-FE-012 | E10: ==Dashboard!C31 -> Attendance UI | F10: ==Dashboard!D31 -> Adithyan N | M10: ==Dashboard!A20 -> TASK-FE-001 | N10: ==Dashboard!C20 -> React Setup | O10: ==Dashboard!D20 -> Adithyan N
D11: ==Dashboard!A32 -> TASK-FE-013 | E11: ==Dashboard!C32 -> Chatbot UI | F11: ==Dashboard!D32 -> Adithyan N | M11: ==Dashboard!A21 -> TASK-FE-002 | N11: ==Dashboard!C21 -> Tailwind Setup | O11: ==Dashboard!D21 -> Adithyan N
D12: ==Dashboard!A33 -> TASK-FE-014 | E12: ==Dashboard!C33 -> Admin Dashboard | F12: ==Dashboard!D33 -> Adithyan N | M12: ==Dashboard!A22 -> TASK-FE-003 | N12: ==Dashboard!C22 -> Routing | O12: ==Dashboard!D22 -> Adithyan N
D13: ==Dashboard!A34 -> TASK-FE-015 | E13: ==Dashboard!C34 -> Notifications UI | F13: ==Dashboard!D34 -> Adithyan N | M13: ==Dashboard!A23 -> TASK-FE-004 | N13: ==Dashboard!C23 -> Protected Routes | O13: ==Dashboard!D23 -> Adithyan N
D14: ==Dashboard!A35 -> TASK-FE-016 | E14: ==Dashboard!C35 -> Responsive Fixes | F14: ==Dashboard!D35 -> Adithyan N | M14: ==Dashboard!A24 -> TASK-FE-005 | N14: ==Dashboard!C24 -> Axios Setup | O14: ==Dashboard!D24 -> Adithyan N
D15: ==Dashboard!A36 -> TASK-FE-017 | E15: ==Dashboard!C36 -> Integration | F15: ==Dashboard!D36 -> Adithyan N | M15: ==Dashboard!A25 -> TASK-FE-006 | N15: ==Dashboard!C25 -> Authentication UI | O15: ==Dashboard!D25 -> Adithyan N
D16: ==Dashboard!A37 -> TASK-FE-018 | E16: ==Dashboard!C37 -> Final UI Testing | F16: ==Dashboard!D37 -> Adithyan N | M16: ==Dashboard!A26 -> TASK-FE-007 | N16: ==Dashboard!C26 -> Citizen Dashboard | O16: ==Dashboard!D26 -> Adithyan N
D17: ==Dashboard!A43 -> TASK-BE-006 | E17: ==Dashboard!C43 -> Attendance APIs | F17: ==Dashboard!D43 -> Muhammad Sanish | M17: ==Dashboard!A38 -> TASK-BE-001 | N17: ==Dashboard!C38 -> Express Setup | O17: ==Dashboard!D38 -> Muhammad Sanish
D18: ==Dashboard!A44 -> TASK-BE-007 | E18: ==Dashboard!C44 -> Feedback APIs | F18: ==Dashboard!D44 -> Muhammad Sanish | M18: ==Dashboard!A39 -> TASK-BE-002 | N18: ==Dashboard!C39 -> JWT Authentication | O18: ==Dashboard!D39 -> Muhammad Sanish
D19: ==Dashboard!A45 -> TASK-BE-008 | E19: ==Dashboard!C45 -> Admin APIs | F19: ==Dashboard!D45 -> Muhammad Sanish | M19: ==Dashboard!A40 -> TASK-BE-003 | N19: ==Dashboard!C40 -> RBAC | O19: ==Dashboard!D40 -> Muhammad Sanish
D20: ==Dashboard!A46 -> TASK-BE-009 | E20: ==Dashboard!C46 -> Audit Logging | F20: ==Dashboard!D46 -> Muhammad Sanish | M20: ==Dashboard!A49 -> TASK-DB-001 | N20: ==Dashboard!C49 -> Core Schema Creation | O20: ==Dashboard!D49 -> Fathima Hana
D21: ==Dashboard!A47 -> TASK-BE-010 | E21: ==Dashboard!C47 -> Middleware | F21: ==Dashboard!D47 -> Muhammad Sanish | M21: ==Dashboard!A50 -> TASK-DB-002 | N21: ==Dashboard!C50 -> Mongoose Models | O21: ==Dashboard!D50 -> Fathima Hana
D22: ==Dashboard!A48 -> TASK-BE-011 | E22: ==Dashboard!C48 -> Security Middleware | F22: ==Dashboard!D48 -> Muhammad Sanish | M22: ==Dashboard!A51 -> TASK-DB-003 | N22: ==Dashboard!C51 -> Relationships | O22: ==Dashboard!D51 -> Fathima Hana
D23: ==Dashboard!A53 -> TASK-DB-005 | E23: ==Dashboard!C53 -> Validation | F23: ==Dashboard!D53 -> Fathima Hana | M23: ==Dashboard!A52 -> TASK-DB-004 | N23: ==Dashboard!C52 -> Indexing | O23: ==Dashboard!D52 -> Fathima Hana
D24: ==Dashboard!A54 -> TASK-DB-006 | E24: ==Dashboard!C54 -> Query Optimization | F24: ==Dashboard!D54 -> Fathima Hana | M24: ==Dashboard!A67 -> TASK-QA-001 | N24: ==Dashboard!C67 -> Test Cases | O24: ==Dashboard!D67 -> Minha Palakkathodi
D25: ==Dashboard!A55 -> TASK-AI-001 | E25: ==Dashboard!C55 -> Gemini Chatbot | F25: ==Dashboard!D55 -> Muhammed Sadik KT | M25: ==Dashboard!A68 -> TASK-QA-002 | N25: ==Dashboard!C68 -> Traceability Matrix | O25: ==Dashboard!D68 -> Minha Palakkathodi
D26: ==Dashboard!A56 -> TASK-AI-002 | E26: ==Dashboard!C56 -> OCR | F26: ==Dashboard!D56 -> Muhammed Sadik KT
D27: ==Dashboard!A57 -> TASK-AI-003 | E27: ==Dashboard!C57 -> AI APIs | F27: ==Dashboard!D57 -> Muhammed Sadik KT
D28: ==Dashboard!A58 -> TASK-AI-004 | E28: ==Dashboard!C58 -> Prompt Engineering | F28: ==Dashboard!D58 -> Muhammed Sadik KT
D29: ==Dashboard!A59 -> TASK-AI-005 | E29: ==Dashboard!C59 -> Face Recognition Core Implementation | F29: ==Dashboard!D59 -> Muhammed Sadik KT
D30: ==Dashboard!A60 -> TASK-FR-001 | E30: ==Dashboard!C60 -> Dataset Collection | F30: ==Dashboard!D60 -> Fadi Ahmed
D31: ==Dashboard!A61 -> TASK-FR-002 | E31: ==Dashboard!C61 -> Prototype Refinement | F31: ==Dashboard!D61 -> Fadi Ahmed
D32: ==Dashboard!A62 -> TASK-FR-003 | E32: ==Dashboard!C62 -> Camera Integration Testing | F32: ==Dashboard!D62 -> Fadi Ahmed
D33: ==Dashboard!A63 -> TASK-FR-004 | E33: ==Dashboard!C63 -> Attendance Workflow Testing | F33: ==Dashboard!D63 -> Fadi Ahmed
D34: ==Dashboard!A64 -> TASK-FR-005 | E34: ==Dashboard!C64 -> Recognition Accuracy Testing | F34: ==Dashboard!D64 -> Fadi Ahmed
D35: ==Dashboard!A65 -> TASK-FR-006 | E35: ==Dashboard!C65 -> Cross-Browser Camera Testing | F35: ==Dashboard!D65 -> Fadi Ahmed
D36: ==Dashboard!A66 -> TASK-FR-007 | E36: ==Dashboard!C66 -> System Integration Testing | F36: ==Dashboard!D66 -> Fadi Ahmed
D37: ==Dashboard!A69 -> TASK-QA-003 | E37: ==Dashboard!C69 -> QA Reports | F37: ==Dashboard!D69 -> Minha Palakkathodi
D38: ==Dashboard!A70 -> TASK-QA-004 | E38: ==Dashboard!C70 -> UAT | F38: ==Dashboard!D70 -> Minha Palakkathodi
D39: ==Dashboard!A71 -> TASK-QA-005 | E39: ==Dashboard!C71 -> Handover Documentation | F39: ==Dashboard!D71 -> Minha Palakkathodi
D40: ==Dashboard!A72 -> TASK-QA-006 | E40: ==Dashboard!C72 -> Documentation Updates | F40: ==Dashboard!D72 -> Minha Palakkathodi

Sheet Sprint 0
A1: Gantt Timeline Plan - Sprint 0 Schedule & Tasks
A2: Task ID | B2: Task Name | C2: Assigned To | D2: Priority | E2: Dependency | F2: Status | G2: Deliverable | H2: Testing Required | I2: Security Check Required | J2: Remarks
A3: ==Dashboard!A16 -> TASK-INF-001 | B3: ==Dashboard!C16 -> MongoDB Atlas Setup | C3: ==Dashboard!D16 -> Adithyan N | D3: ==Dashboard!E16 -> Critical | E3: ==Dashboard!I16 -> None | F3: ==Dashboard!F16 -> Completed | G3: Live MongoDB Atlas cluster with restricted access policies | H3: Yes | I3: Yes | J3: ==Dashboard!L16 -> Admin controls configured and database connection verified
A4: ==Dashboard!A17 -> TASK-INF-002 | B4: ==Dashboard!C17 -> Environment Configuration | C4: ==Dashboard!D17 -> Muhammad Sanish | D4: ==Dashboard!E17 -> High | E4: ==Dashboard!I17 -> None | F4: ==Dashboard!F17 -> Completed | G4: .env.example environment configuration template | H4: Yes | I4: Yes | J4: ==Dashboard!L17 -> No secrets committed, configuration structure validated
A5: ==Dashboard!A20 -> TASK-FE-001 | B5: ==Dashboard!C20 -> React Setup | C5: ==Dashboard!D20 -> Adithyan N | D5: ==Dashboard!E20 -> High | E5: ==Dashboard!I20 -> None | F5: ==Dashboard!F20 -> Completed | G5: React application project template structure initialized | H5: Yes | I5: Yes | J5: ==Dashboard!L20 -> Vite React scaffolded with standard directory layout
A6: ==Dashboard!A21 -> TASK-FE-002 | B6: ==Dashboard!C21 -> Tailwind Setup | C6: ==Dashboard!D21 -> Adithyan N | D6: ==Dashboard!E21 -> High | E6: ==Dashboard!I21 -> TASK-FE-001 | F6: ==Dashboard!F21 -> Completed | G6: Tailwind CSS utility config and design theme tokens loaded | H6: Yes | I6: Yes | J6: ==Dashboard!L21 -> Tailwind configuration, colors, and typography set up
A7: ==Dashboard!A49 -> TASK-DB-001 | B7: ==Dashboard!C49 -> Core Schema Creation | C7: ==Dashboard!D49 -> Fathima Hana | D7: ==Dashboard!E49 -> Critical | E7: ==Dashboard!I49 -> TASK-INF-001 | F7: ==Dashboard!F49 -> Completed | G7: Initial collections setup scripts (14 mandatory schemas) | H7: Yes | I7: Yes | J7: ==Dashboard!L49 -> Support: Adithyan N. Constraints loaded and DB connection active

Sheet Day 1
A1: Gantt Timeline Plan - Day 1 Schedule & Tasks
A2: Task ID | B2: Task Name | C2: Assigned To | D2: Priority | E2: Dependency | F2: Status | G2: Deliverable | H2: Testing Required | I2: Security Check Required | J2: Remarks
A3: ==Dashboard!A18 -> TASK-INF-003 | B3: ==Dashboard!C18 -> Logging Infrastructure Setup | C3: ==Dashboard!D18 -> Muhammad Sanish | D3: ==Dashboard!E18 -> Medium | E3: ==Dashboard!I18 -> TASK-INF-002 | F3: ==Dashboard!F18 -> Completed | G3: Winston/Morgan logger script with data redaction middleware | H3: Yes | I3: Yes | J3: ==Dashboard!L18 -> Sensitive data redacted in Winston streams
A4: ==Dashboard!A22 -> TASK-FE-003 | B4: ==Dashboard!C22 -> Routing | C4: ==Dashboard!D22 -> Adithyan N | D4: ==Dashboard!E22 -> High | E4: ==Dashboard!I22 -> TASK-FE-001 | F4: ==Dashboard!F22 -> Completed | G4: React Router routes paths configuration mappings | H4: Yes | I4: Yes | J4: ==Dashboard!L22 -> Browser router routes setup, layout routes configured
A5: ==Dashboard!A23 -> TASK-FE-004 | B5: ==Dashboard!C23 -> Protected Routes | C5: ==Dashboard!D23 -> Adithyan N | D5: ==Dashboard!E23 -> High | E5: ==Dashboard!I23 -> TASK-FE-003 | F5: ==Dashboard!F23 -> Completed | G5: Route guard elements validation checking tokens | H5: Yes | I5: Yes | J5: ==Dashboard!L23 -> Client RBAC guard integrated with token decoder
A6: ==Dashboard!A24 -> TASK-FE-005 | B6: ==Dashboard!C24 -> Axios Setup | C6: ==Dashboard!D24 -> Adithyan N | D6: ==Dashboard!E24 -> High | E6: ==Dashboard!I24 -> None | F6: ==Dashboard!F24 -> Completed | G6: Axios client instance configured with auth header interceptors | H6: Yes | I6: Yes | J6: ==Dashboard!L24 -> JWT interceptor setup, retry limits configured
A7: ==Dashboard!A38 -> TASK-BE-001 | B7: ==Dashboard!C38 -> Express Setup | C7: ==Dashboard!D38 -> Muhammad Sanish | D7: ==Dashboard!E38 -> Critical | E7: ==Dashboard!I38 -> TASK-INF-002 | F7: ==Dashboard!F38 -> Completed | G7: Scaffolded Express app configured with helmet CORS rates filters | H7: Yes | I7: Yes | J7: ==Dashboard!L38 -> Winston logger active and CORS rules applied
A8: ==Dashboard!A50 -> TASK-DB-002 | B8: ==Dashboard!C50 -> Mongoose Models | C8: ==Dashboard!D50 -> Fathima Hana | D8: ==Dashboard!E50 -> Critical | E8: ==Dashboard!I50 -> TASK-DB-001 | F8: ==Dashboard!F50 -> Completed | G8: Mongoose schemas definitions users, complaints, tracking | H8: Yes | I8: Yes | J8: ==Dashboard!L50 -> Support: Adithyan N. Unique key bounds and validators active
A9: ==Dashboard!A68 -> TASK-QA-002 | B9: ==Dashboard!C68 -> Traceability Matrix | C9: ==Dashboard!D68 -> Minha Palakkathodi | D9: ==Dashboard!E68 -> High | E9: ==Dashboard!I68 -> None | F9: ==Dashboard!F68 -> Completed | G9: Requirements validation spreadsheet mapping models to routes | H9: Yes | I9: Yes | J9: ==Dashboard!L68 -> SRS mappings verified and formatted

Sheet Day 2
A1: Gantt Timeline Plan - Day 2 Schedule & Tasks
A2: Task ID | B2: Task Name | C2: Assigned To | D2: Priority | E2: Dependency | F2: Status | G2: Deliverable | H2: Testing Required | I2: Security Check Required | J2: Remarks
A3: ==Dashboard!A25 -> TASK-FE-006 | B3: ==Dashboard!C25 -> Authentication UI | C3: ==Dashboard!D25 -> Adithyan N | D3: ==Dashboard!E25 -> High | E3: ==Dashboard!I25 -> TASK-FE-004 | F3: ==Dashboard!F25 -> Completed | G3: Responsive login, register, and password reset form grids | H3: Yes | I3: Yes | J3: ==Dashboard!L25 -> Secure cookie setup and form validations active
A4: ==Dashboard!A26 -> TASK-FE-007 | B4: ==Dashboard!C26 -> Citizen Dashboard | C4: ==Dashboard!D26 -> Adithyan N | D4: ==Dashboard!E26 -> High | E4: ==Dashboard!I26 -> TASK-FE-004 | F4: ==Dashboard!F26 -> Completed | G4: Citizen portal layout display grids with ticket log table | H4: Yes | I4: Yes | J4: ==Dashboard!L26 -> Overview console with responsive metrics cards active
A5: ==Dashboard!A39 -> TASK-BE-002 | B5: ==Dashboard!C39 -> JWT Authentication | C5: ==Dashboard!D39 -> Muhammad Sanish | D5: ==Dashboard!E39 -> Critical | E5: ==Dashboard!I39 -> TASK-BE-001 | F5: ==Dashboard!F39 -> Completed | G5: Signup, Login, and Session controller routers with tokens | H5: Yes | I5: Yes | J5: ==Dashboard!L39 -> Bcrypt hashed passwords verified on register
A6: ==Dashboard!A40 -> TASK-BE-003 | B6: ==Dashboard!C40 -> RBAC | C6: ==Dashboard!D40 -> Muhammad Sanish | D6: ==Dashboard!E40 -> Critical | E6: ==Dashboard!I40 -> TASK-BE-002 | F6: ==Dashboard!F40 -> Completed | G6: Authorization middleware gating api endpoints matching roles | H6: Yes | I6: Yes | J6: ==Dashboard!L40 -> Token payload checks for Citizen, Staff, Admin active
A7: ==Dashboard!A67 -> TASK-QA-001 | B7: ==Dashboard!C67 -> Test Cases | C7: ==Dashboard!D67 -> Minha Palakkathodi | D7: ==Dashboard!E67 -> High | E7: ==Dashboard!I67 -> None | F7: ==Dashboard!F67 -> Completed | G7: Functional test logs templates citizen/staff workflows | H7: Yes | I7: Yes | J7: ==Dashboard!L67 -> Validation schedules and manual test logs created

Sheet Day 3
A1: Gantt Timeline Plan - Day 3 Schedule & Tasks
A2: Task ID | B2: Task Name | C2: Assigned To | D2: Priority | E2: Dependency | F2: Status | G2: Deliverable | H2: Testing Required | I2: Security Check Required | J2: Remarks
A3: ==Dashboard!A27 -> TASK-FE-008 | B3: ==Dashboard!C27 -> Complaint UI | C3: ==Dashboard!D27 -> Adithyan N | D3: ==Dashboard!E27 -> High | E3: ==Dashboard!I27 -> TASK-FE-007 | F3: ==Dashboard!F27 -> In Progress | G3: Grievance registration intakes forms with attachment fields | H3: Yes | I3: Yes | J3: ==Dashboard!L27 -> Input sanitizations in progress, UI layout complete
A4: ==Dashboard!A28 -> TASK-FE-009 | B4: ==Dashboard!C28 -> File Tracking UI | C4: ==Dashboard!D28 -> Adithyan N | D4: ==Dashboard!E28 -> Medium | E4: ==Dashboard!I28 -> TASK-FE-005 | F4: ==Dashboard!F28 -> In Progress | G4: Public lookup files status visual progress timelines tracker | H4: Yes | I4: Yes | J4: ==Dashboard!L28 -> Timeline progress bar rendering in progress
A5: ==Dashboard!A41 -> TASK-BE-004 | B5: ==Dashboard!C41 -> Complaint APIs | C5: ==Dashboard!D41 -> Muhammad Sanish | D5: ==Dashboard!E41 -> High | E5: ==Dashboard!I41 -> TASK-BE-003 | F5: ==Dashboard!F41 -> Review | G5: GET / POST / PUT complaints routers with ownership filters | H5: Yes | I5: Yes | J5: ==Dashboard!L41 -> Transaction logs active, code complete, undergoing review
A6: ==Dashboard!A42 -> TASK-BE-005 | B6: ==Dashboard!C42 -> File Tracking APIs | C6: ==Dashboard!D42 -> Muhammad Sanish | D6: ==Dashboard!E42 -> Medium | E6: ==Dashboard!I42 -> TASK-BE-003 | F6: ==Dashboard!F42 -> Review | G6: Public tracking API endpoints hiding restricted properties | H6: Yes | I6: Yes | J6: ==Dashboard!L42 -> Escaped tracking strings active, under API review
A7: ==Dashboard!A51 -> TASK-DB-003 | B7: ==Dashboard!C51 -> Relationships | C7: ==Dashboard!D51 -> Fathima Hana | D7: ==Dashboard!E51 -> High | E7: ==Dashboard!I51 -> TASK-DB-002 | F7: ==Dashboard!F51 -> Completed | G7: Foreign references configurations between users and complaints | H7: Yes | I7: Yes | J7: ==Dashboard!L51 -> Support: Adithyan N. Model referencing setup and verified
A8: ==Dashboard!A52 -> TASK-DB-004 | B8: ==Dashboard!C52 -> Indexing | C8: ==Dashboard!D52 -> Fathima Hana | D8: ==Dashboard!E52 -> Medium | E8: ==Dashboard!I52 -> TASK-DB-002 | F8: ==Dashboard!F52 -> Completed | G8: Unique indices on user IDs and geospatial tags on complaints | H8: Yes | I8: Yes | J8: ==Dashboard!L52 -> Support: Adithyan N. Indexes configured, query execution fast

Sheet Day 4
A1: Gantt Timeline Plan - Day 4 Schedule & Tasks
A2: Task ID | B2: Task Name | C2: Assigned To | D2: Priority | E2: Dependency | F2: Status | G2: Deliverable | H2: Testing Required | I2: Security Check Required | J2: Remarks
A3: ==Dashboard!A30 -> TASK-FE-011 | B3: ==Dashboard!C30 -> Staff Dashboard UI | C3: ==Dashboard!D30 -> Adithyan N | D3: ==Dashboard!E30 -> High | E3: ==Dashboard!I30 -> TASK-FE-004 | F3: ==Dashboard!F30 -> Not Started | G3: Staff operations control tables and status assignment buttons | H3: Yes | I3: Yes | J3: ==Dashboard!L30 -> Employee operations view blueprint set
A4: ==Dashboard!A31 -> TASK-FE-012 | B4: ==Dashboard!C31 -> Attendance UI | C4: ==Dashboard!D31 -> Adithyan N | D4: ==Dashboard!E31 -> High | E4: ==Dashboard!I31 -> TASK-FE-011 | F4: ==Dashboard!F31 -> Not Started | G4: Consent prompt and webcam feed canvas punch frames | H4: Yes | I4: Yes | J4: ==Dashboard!L31 -> Liveness scan layout mock complete
A5: ==Dashboard!A43 -> TASK-BE-006 | B5: ==Dashboard!C43 -> Attendance APIs | C5: ==Dashboard!D43 -> Muhammad Sanish | D5: ==Dashboard!E43 -> High | E5: ==Dashboard!I43 -> TASK-BE-003 | F5: ==Dashboard!F43 -> Not Started | G5: Consent verification punches and fallbacks endpoints adapters | H5: Yes | I5: Yes | J5: ==Dashboard!L43 -> Secure verification punches adapter specifications ready
A6: ==Dashboard!A59 -> TASK-AI-005 | B6: ==Dashboard!C59 -> Face Recognition Core Implementation | C6: ==Dashboard!D59 -> Muhammed Sadik KT | D6: ==Dashboard!E59 -> Critical | E6: ==Dashboard!I59 -> None | F6: ==Dashboard!F59 -> Not Started | G6: Python face matching algorithms calculating liveness scores | H6: Yes | I6: Yes | J6: ==Dashboard!L59 -> Volatile RAM comparison model designed
A7: ==Dashboard!A60 -> TASK-FR-001 | B7: ==Dashboard!C60 -> Dataset Collection | C7: ==Dashboard!D60 -> Fadi Ahmed | D7: ==Dashboard!E60 -> Medium | E7: ==Dashboard!I60 -> None | F7: ==Dashboard!F60 -> Not Started | G7: Standardized profile template datasets for staff registration calibrator | H7: Yes | I7: Yes | J7: ==Dashboard!L60 -> Offline template protection standards set
A8: ==Dashboard!A61 -> TASK-FR-002 | B8: ==Dashboard!C61 -> Prototype Refinement | C8: ==Dashboard!D61 -> Fadi Ahmed | D8: ==Dashboard!E61 -> High | E8: ==Dashboard!I61 -> TASK-AI-005 | F8: ==Dashboard!F61 -> Not Started | G8: Optimized landmarks matrix comparison module testing files | H8: Yes | I8: Yes | J8: ==Dashboard!L61 -> Anti-spoofing test frameworks ready
A9: ==Dashboard!A62 -> TASK-FR-003 | B9: ==Dashboard!C62 -> Camera Integration Testing | C9: ==Dashboard!D62 -> Fadi Ahmed | D9: ==Dashboard!E62 -> Medium | E9: ==Dashboard!I62 -> None | F9: ==Dashboard!F62 -> Not Started | G9: HTML webcam access wrapper components tests reports | H9: Yes | I9: Yes | J9: ==Dashboard!L62 -> Zero frame storage validation script written

Sheet Day 5
A1: Gantt Timeline Plan - Day 5 Schedule & Tasks
A2: Task ID | B2: Task Name | C2: Assigned To | D2: Priority | E2: Dependency | F2: Status | G2: Deliverable | H2: Testing Required | I2: Security Check Required | J2: Remarks
A3: ==Dashboard!A29 -> TASK-FE-010 | B3: ==Dashboard!C29 -> Feedback UI | C3: ==Dashboard!D29 -> Adithyan N | D3: ==Dashboard!E29 -> Medium | E3: ==Dashboard!I29 -> TASK-FE-008 | F3: ==Dashboard!F29 -> Not Started | G3: Satisfaction ratings form controls locking completed complaints | H3: Yes | I3: Yes | J3: ==Dashboard!L29 -> Satisfaction ratings form mockup completed
A4: ==Dashboard!A32 -> TASK-FE-013 | B4: ==Dashboard!C32 -> Chatbot UI | C4: ==Dashboard!D32 -> Adithyan N | D4: ==Dashboard!E32 -> Medium | E4: ==Dashboard!I32 -> TASK-FE-005 | F4: ==Dashboard!F32 -> Not Started | G4: Chat container overlays with scrolling dialog logs interface | H4: Yes | I4: Yes | J4: ==Dashboard!L32 -> Gemini chat console overlay designed
A5: ==Dashboard!A33 -> TASK-FE-014 | B5: ==Dashboard!C33 -> Admin Dashboard | C5: ==Dashboard!D33 -> Adithyan N | D5: ==Dashboard!E33 -> High | E5: ==Dashboard!I33 -> TASK-FE-004 | F5: ==Dashboard!F33 -> Not Started | G5: User management console and Audit system dashboard panels | H5: Yes | I5: Yes | J5: ==Dashboard!L33 -> Audit logs reviewer views prepared
A6: ==Dashboard!A44 -> TASK-BE-007 | B6: ==Dashboard!C44 -> Feedback APIs | C6: ==Dashboard!D44 -> Muhammad Sanish | D6: ==Dashboard!E44 -> Medium | E6: ==Dashboard!I44 -> TASK-BE-004 | F6: ==Dashboard!F44 -> Not Started | G6: Grievance feedback ratings submission routers locking ticket | H6: Yes | I6: Yes | J6: ==Dashboard!L44 -> Complaints lock logic active draft
A7: ==Dashboard!A45 -> TASK-BE-008 | B7: ==Dashboard!C45 -> Admin APIs | C7: ==Dashboard!D45 -> Muhammad Sanish | D7: ==Dashboard!E45 -> High | E7: ==Dashboard!I45 -> TASK-BE-003 | F7: ==Dashboard!F45 -> Not Started | G7: Administrative configs and system parameter modifications APIs | H7: Yes | I7: Yes | J7: ==Dashboard!L45 -> Admin RBAC validation middlewares declared
A8: ==Dashboard!A55 -> TASK-AI-001 | B8: ==Dashboard!C55 -> Gemini Chatbot | C8: ==Dashboard!D55 -> Muhammed Sadik KT | D8: ==Dashboard!E55 -> High | E8: ==Dashboard!I55 -> None | F8: ==Dashboard!F55 -> Not Started | G8: Grounded chat orchestrator wrapper using Gemini APIs models | H8: Yes | I8: Yes | J8: ==Dashboard!L55 -> RAG context bounds applied
A9: ==Dashboard!A56 -> TASK-AI-002 | B9: ==Dashboard!C56 -> OCR | C9: ==Dashboard!D56 -> Muhammed Sadik KT | D9: ==Dashboard!E56 -> Medium | E9: ==Dashboard!I56 -> None | F9: ==Dashboard!F56 -> Not Started | G9: PDF/Image metadata scanner extracting doc credentials details | H9: Yes | I9: Yes | J9: ==Dashboard!L56 -> Secure local storage sandbox specs
A10: ==Dashboard!A57 -> TASK-AI-003 | B10: ==Dashboard!C57 -> AI APIs | C10: ==Dashboard!D57 -> Muhammed Sadik KT | D10: ==Dashboard!E57 -> High | E10: ==Dashboard!I57 -> None | F10: ==Dashboard!F57 -> Not Started | G10: Microservice endpoints parsing citizen attachments and query logs | H10: Yes | I10: Yes | J10: ==Dashboard!L57 -> Secure credentials configuration detailed
A11: ==Dashboard!A58 -> TASK-AI-004 | B11: ==Dashboard!C58 -> Prompt Engineering | C11: ==Dashboard!D58 -> Muhammed Sadik KT | D11: ==Dashboard!E58 -> Medium | E11: ==Dashboard!I58 -> TASK-AI-001 | F11: ==Dashboard!F58 -> Not Started | G11: Prompt system blueprints grounding chatbot in municipality docs | H11: Yes | I11: Yes | J11: ==Dashboard!L58 -> Prompt injection guards drafted
A12: ==Dashboard!A63 -> TASK-FR-004 | B12: ==Dashboard!C63 -> Attendance Workflow Testing | C12: ==Dashboard!D63 -> Fadi Ahmed | D12: ==Dashboard!E63 -> High | E12: ==Dashboard!I63 -> TASK-FR-003 | F12: ==Dashboard!F63 -> Not Started | G12: Webcam punch validation tracing logs check-ins | H12: Yes | I12: Yes | J12: ==Dashboard!L63 -> Consent constraints gating check template
A13: ==Dashboard!A64 -> TASK-FR-005 | B13: ==Dashboard!C64 -> Recognition Accuracy Testing | C13: ==Dashboard!D64 -> Fadi Ahmed | D13: ==Dashboard!E64 -> High | E13: ==Dashboard!I64 -> TASK-FR-002 | F13: ==Dashboard!F64 -> Not Started | G13: Accuracy metrics checking FAR and FRR scales results log | H13: Yes | I13: Yes | J13: ==Dashboard!L64 -> Robustness audit report format ready

Sheet Day 6
A1: Gantt Timeline Plan - Day 6 Schedule & Tasks
A2: Task ID | B2: Task Name | C2: Assigned To | D2: Priority | E2: Dependency | F2: Status | G2: Deliverable | H2: Testing Required | I2: Security Check Required | J2: Remarks
A3: ==Dashboard!A34 -> TASK-FE-015 | B3: ==Dashboard!C34 -> Notifications UI | C3: ==Dashboard!D34 -> Adithyan N | D3: ==Dashboard!E34 -> Medium | E3: ==Dashboard!I34 -> TASK-FE-005 | F3: ==Dashboard!F34 -> Not Started | G3: Alert toasts dialogs and global notifications dropdown list | H3: Yes | I3: Yes | J3: ==Dashboard!L34 -> Dynamic web toasts configuration ready
A4: ==Dashboard!A35 -> TASK-FE-016 | B4: ==Dashboard!C35 -> Responsive Fixes | C4: ==Dashboard!D35 -> Adithyan N | D4: ==Dashboard!E35 -> Medium | E4: ==Dashboard!I35 -> TASK-FE-014 | F4: ==Dashboard!F35 -> Not Started | G4: CSS media queries patches verifying mobile responsiveness | H4: Yes | I4: Yes | J4: ==Dashboard!L35 -> Mobile views checking strategy defined
A5: ==Dashboard!A36 -> TASK-FE-017 | B5: ==Dashboard!C36 -> Integration | C5: ==Dashboard!D36 -> Adithyan N | D5: ==Dashboard!E36 -> High | E5: ==Dashboard!I36 -> TASK-FE-015 | F5: ==Dashboard!F36 -> Not Started | G5: Frontend view layouts wired to active backend API endpoints | H5: Yes | I5: Yes | J5: ==Dashboard!L36 -> All endpoints integration mapping checklist
A6: ==Dashboard!A46 -> TASK-BE-009 | B6: ==Dashboard!C46 -> Audit Logging | C6: ==Dashboard!D46 -> Muhammad Sanish | D6: ==Dashboard!E46 -> High | E6: ==Dashboard!I46 -> TASK-BE-001 | F6: ==Dashboard!F46 -> Not Started | G6: Transactional logger tracking key security database modifications | H6: Yes | I6: Yes | J6: ==Dashboard!L46 -> Log write validations schema prepared
A7: ==Dashboard!A47 -> TASK-BE-010 | B7: ==Dashboard!C47 -> Middleware | C7: ==Dashboard!D47 -> Muhammad Sanish | D7: ==Dashboard!E47 -> High | E7: ==Dashboard!I47 -> TASK-BE-001 | F7: ==Dashboard!F47 -> Not Started | G7: Centralized error handlers and request ID injector scripts | H7: Yes | I7: Yes | J7: ==Dashboard!L47 -> Standard middlewares pipeline mapped
A8: ==Dashboard!A48 -> TASK-BE-011 | B8: ==Dashboard!C48 -> Security Middleware | C8: ==Dashboard!D48 -> Muhammad Sanish | D8: ==Dashboard!E48 -> Critical | E8: ==Dashboard!I48 -> TASK-BE-001 | F8: ==Dashboard!F48 -> Not Started | G8: Anti-NoSQL injections and CAPTCHA validators middlewares | H8: Yes | I8: Yes | J8: ==Dashboard!L48 -> SameSite token configurations specified
A9: ==Dashboard!A53 -> TASK-DB-005 | B9: ==Dashboard!C53 -> Validation | C9: ==Dashboard!D53 -> Fathima Hana | D9: ==Dashboard!E53 -> High | E9: ==Dashboard!I53 -> TASK-DB-002 | F9: ==Dashboard!F53 -> Not Started | G9: Custom validation functions sanitizing inputs before DB write | H9: Yes | I9: Yes | J9: ==Dashboard!L53 -> Support: Adithyan N. Format checks drafted
A10: ==Dashboard!A54 -> TASK-DB-006 | B10: ==Dashboard!C54 -> Query Optimization | C10: ==Dashboard!D54 -> Fathima Hana | D10: ==Dashboard!E54 -> Medium | E10: ==Dashboard!I54 -> TASK-DB-004 | F10: ==Dashboard!F54 -> Not Started | G10: Explain query audit logs verifying efficient index mappings | H10: Yes | I10: Yes | J10: ==Dashboard!L54 -> Support: Adithyan N. Query optimization strategy defined
A11: ==Dashboard!A65 -> TASK-FR-006 | B11: ==Dashboard!C65 -> Cross-Browser Camera Testing | C11: ==Dashboard!D65 -> Fadi Ahmed | D11: ==Dashboard!E65 -> Medium | E11: ==Dashboard!I65 -> TASK-FR-003 | F11: ==Dashboard!F65 -> Not Started | G11: Webcam rendering log on Safari, Firefox, Chrome, Edge | H11: Yes | I11: Yes | J11: ==Dashboard!L65 -> Web permissions tests blueprint
A12: ==Dashboard!A66 -> TASK-FR-007 | B12: ==Dashboard!C66 -> System Integration Testing | C12: ==Dashboard!D66 -> Fadi Ahmed | D12: ==Dashboard!E66 -> High | E12: ==Dashboard!I66 -> TASK-FR-004 | F12: ==Dashboard!F66 -> Not Started | G12: Biometrics validation checklist verifying dashboard updates logs | H12: Yes | I12: Yes | J12: ==Dashboard!L66 -> RBAC boundary check verified
A13: ==Dashboard!A69 -> TASK-QA-003 | B13: ==Dashboard!C69 -> QA Reports | C13: ==Dashboard!D69 -> Minha Palakkathodi | D13: ==Dashboard!E69 -> Medium | E13: ==Dashboard!I69 -> None | F13: ==Dashboard!F69 -> Not Started | G13: Completed QA pass summaries checklist log sheet | H13: Yes | I13: Yes | J13: ==Dashboard!L69 -> Sprint review reports templates prepared

Sheet Day 7
A1: Gantt Timeline Plan - Day 7 Schedule & Tasks
A2: Task ID | B2: Task Name | C2: Assigned To | D2: Priority | E2: Dependency | F2: Status | G2: Deliverable | H2: Testing Required | I2: Security Check Required | J2: Remarks
A3: ==Dashboard!A19 -> TASK-INF-004 | B3: ==Dashboard!C19 -> Deployment Environment Preparation | C3: ==Dashboard!D19 -> Adithyan N | D3: ==Dashboard!E19 -> Medium | E3: ==Dashboard!I19 -> None | F3: ==Dashboard!F19 -> Not Started | G3: Render/Vercel production environment config sheets | H3: Yes | I3: Yes | J3: ==Dashboard!L19 -> Deployment scripts drafted, hosting environments initialized
A4: ==Dashboard!A37 -> TASK-FE-018 | B4: ==Dashboard!C37 -> Final UI Testing | C4: ==Dashboard!D37 -> Adithyan N | D4: ==Dashboard!E37 -> High | E4: ==Dashboard!I37 -> TASK-FE-017 | F4: ==Dashboard!F37 -> Not Started | G4: E2E user interface visual checking verification report | H4: Yes | I4: Yes | J4: ==Dashboard!L37 -> QA Visual signoff template configured
A5: ==Dashboard!A70 -> TASK-QA-004 | B5: ==Dashboard!C70 -> UAT | C5: ==Dashboard!D70 -> Minha Palakkathodi | D5: ==Dashboard!E70 -> High | E5: ==Dashboard!I70 -> None | F5: ==Dashboard!F70 -> Not Started | G5: User acceptance tracking forms templates validation | H5: Yes | I5: Yes | J5: ==Dashboard!L70 -> Acceptance signs template setup
A6: ==Dashboard!A71 -> TASK-QA-005 | B6: ==Dashboard!C71 -> Handover Documentation | C6: ==Dashboard!D71 -> Minha Palakkathodi | D6: ==Dashboard!E71 -> High | E6: ==Dashboard!I71 -> None | F6: ==Dashboard!F71 -> Not Started | G6: Consolidated developer guide and handover checklist documentation | H6: Yes | I6: Yes | J6: ==Dashboard!L71 -> Official handoff portfolio templates drafted
A7: ==Dashboard!A72 -> TASK-QA-006 | B7: ==Dashboard!C72 -> Documentation Updates | C7: ==Dashboard!D72 -> Minha Palakkathodi | D7: ==Dashboard!E72 -> Medium | E7: ==Dashboard!I72 -> None | F7: ==Dashboard!F72 -> Not Started | G7: Updated README and master documents folders checklists | H7: Yes | I7: Yes | J7: ==Dashboard!L72 -> Final directory inventory check template

Sheet Backend Tasks
A1: Backend Tasks (Module Lead: Muhammad Sanish)
A2: Task ID | B2: Task Name | C2: Assigned To | D2: Priority | E2: Status | F2: Due Day | G2: Dependency | H2: Testing Status | I2: Remarks
A3: ==Dashboard!A38 -> TASK-BE-001 | B3: ==Dashboard!C38 -> Express Setup | C3: ==Dashboard!D38 -> Muhammad Sanish | D3: ==Dashboard!E38 -> Critical | E3: ==Dashboard!F38 -> Completed | F3: ==Dashboard!H38 -> Day 1 | G3: ==Dashboard!I38 -> TASK-INF-002 | H3: ==Dashboard!J38 -> Completed | I3: ==Dashboard!L38 -> Winston logger active and CORS rules applied
A4: ==Dashboard!A39 -> TASK-BE-002 | B4: ==Dashboard!C39 -> JWT Authentication | C4: ==Dashboard!D39 -> Muhammad Sanish | D4: ==Dashboard!E39 -> Critical | E4: ==Dashboard!F39 -> Completed | F4: ==Dashboard!H39 -> Day 2 | G4: ==Dashboard!I39 -> TASK-BE-001 | H4: ==Dashboard!J39 -> Completed | I4: ==Dashboard!L39 -> Bcrypt hashed passwords verified on register
A5: ==Dashboard!A40 -> TASK-BE-003 | B5: ==Dashboard!C40 -> RBAC | C5: ==Dashboard!D40 -> Muhammad Sanish | D5: ==Dashboard!E40 -> Critical | E5: ==Dashboard!F40 -> Completed | F5: ==Dashboard!H40 -> Day 2 | G5: ==Dashboard!I40 -> TASK-BE-002 | H5: ==Dashboard!J40 -> Completed | I5: ==Dashboard!L40 -> Token payload checks for Citizen, Staff, Admin active
A6: ==Dashboard!A41 -> TASK-BE-004 | B6: ==Dashboard!C41 -> Complaint APIs | C6: ==Dashboard!D41 -> Muhammad Sanish | D6: ==Dashboard!E41 -> High | E6: ==Dashboard!F41 -> Review | F6: ==Dashboard!H41 -> Day 3 | G6: ==Dashboard!I41 -> TASK-BE-003 | H6: ==Dashboard!J41 -> Completed | I6: ==Dashboard!L41 -> Transaction logs active, code complete, undergoing review
A7: ==Dashboard!A42 -> TASK-BE-005 | B7: ==Dashboard!C42 -> File Tracking APIs | C7: ==Dashboard!D42 -> Muhammad Sanish | D7: ==Dashboard!E42 -> Medium | E7: ==Dashboard!F42 -> Review | F7: ==Dashboard!H42 -> Day 3 | G7: ==Dashboard!I42 -> TASK-BE-003 | H7: ==Dashboard!J42 -> Completed | I7: ==Dashboard!L42 -> Escaped tracking strings active, under API review
A8: ==Dashboard!A43 -> TASK-BE-006 | B8: ==Dashboard!C43 -> Attendance APIs | C8: ==Dashboard!D43 -> Muhammad Sanish | D8: ==Dashboard!E43 -> High | E8: ==Dashboard!F43 -> Not Started | F8: ==Dashboard!H43 -> Day 4 | G8: ==Dashboard!I43 -> TASK-BE-003 | H8: ==Dashboard!J43 -> Pending | I8: ==Dashboard!L43 -> Secure verification punches adapter specifications ready
A9: ==Dashboard!A44 -> TASK-BE-007 | B9: ==Dashboard!C44 -> Feedback APIs | C9: ==Dashboard!D44 -> Muhammad Sanish | D9: ==Dashboard!E44 -> Medium | E9: ==Dashboard!F44 -> Not Started | F9: ==Dashboard!H44 -> Day 5 | G9: ==Dashboard!I44 -> TASK-BE-004 | H9: ==Dashboard!J44 -> Pending | I9: ==Dashboard!L44 -> Complaints lock logic active draft
A10: ==Dashboard!A45 -> TASK-BE-008 | B10: ==Dashboard!C45 -> Admin APIs | C10: ==Dashboard!D45 -> Muhammad Sanish | D10: ==Dashboard!E45 -> High | E10: ==Dashboard!F45 -> Not Started | F10: ==Dashboard!H45 -> Day 5 | G10: ==Dashboard!I45 -> TASK-BE-003 | H10: ==Dashboard!J45 -> Pending | I10: ==Dashboard!L45 -> Admin RBAC validation middlewares declared
A11: ==Dashboard!A46 -> TASK-BE-009 | B11: ==Dashboard!C46 -> Audit Logging | C11: ==Dashboard!D46 -> Muhammad Sanish | D11: ==Dashboard!E46 -> High | E11: ==Dashboard!F46 -> Not Started | F11: ==Dashboard!H46 -> Day 6 | G11: ==Dashboard!I46 -> TASK-BE-001 | H11: ==Dashboard!J46 -> Pending | I11: ==Dashboard!L46 -> Log write validations schema prepared
A12: ==Dashboard!A47 -> TASK-BE-010 | B12: ==Dashboard!C47 -> Middleware | C12: ==Dashboard!D47 -> Muhammad Sanish | D12: ==Dashboard!E47 -> High | E12: ==Dashboard!F47 -> Not Started | F12: ==Dashboard!H47 -> Day 6 | G12: ==Dashboard!I47 -> TASK-BE-001 | H12: ==Dashboard!J47 -> Pending | I12: ==Dashboard!L47 -> Standard middlewares pipeline mapped
A13: ==Dashboard!A48 -> TASK-BE-011 | B13: ==Dashboard!C48 -> Security Middleware | C13: ==Dashboard!D48 -> Muhammad Sanish | D13: ==Dashboard!E48 -> Critical | E13: ==Dashboard!F48 -> Not Started | F13: ==Dashboard!H48 -> Day 6 | G13: ==Dashboard!I48 -> TASK-BE-001 | H13: ==Dashboard!J48 -> Pending | I13: ==Dashboard!L48 -> SameSite token configurations specified

Sheet Frontend Tasks
A1: Frontend Tasks (Module Lead: Adithyan N)
A2: Task ID | B2: Task Name | C2: Assigned To | D2: Priority | E2: Status | F2: Due Day | G2: Dependency | H2: Testing Status | I2: Remarks
A3: ==Dashboard!A20 -> TASK-FE-001 | B3: ==Dashboard!C20 -> React Setup | C3: ==Dashboard!D20 -> Adithyan N | D3: ==Dashboard!E20 -> High | E3: ==Dashboard!F20 -> Completed | F3: ==Dashboard!H20 -> Sprint 0 | G3: ==Dashboard!I20 -> None | H3: ==Dashboard!J20 -> Completed | I3: ==Dashboard!L20 -> Vite React scaffolded with standard directory layout
A4: ==Dashboard!A21 -> TASK-FE-002 | B4: ==Dashboard!C21 -> Tailwind Setup | C4: ==Dashboard!D21 -> Adithyan N | D4: ==Dashboard!E21 -> High | E4: ==Dashboard!F21 -> Completed | F4: ==Dashboard!H21 -> Sprint 0 | G4: ==Dashboard!I21 -> TASK-FE-001 | H4: ==Dashboard!J21 -> Completed | I4: ==Dashboard!L21 -> Tailwind configuration, colors, and typography set up
A5: ==Dashboard!A22 -> TASK-FE-003 | B5: ==Dashboard!C22 -> Routing | C5: ==Dashboard!D22 -> Adithyan N | D5: ==Dashboard!E22 -> High | E5: ==Dashboard!F22 -> Completed | F5: ==Dashboard!H22 -> Day 1 | G5: ==Dashboard!I22 -> TASK-FE-001 | H5: ==Dashboard!J22 -> Completed | I5: ==Dashboard!L22 -> Browser router routes setup, layout routes configured
A6: ==Dashboard!A23 -> TASK-FE-004 | B6: ==Dashboard!C23 -> Protected Routes | C6: ==Dashboard!D23 -> Adithyan N | D6: ==Dashboard!E23 -> High | E6: ==Dashboard!F23 -> Completed | F6: ==Dashboard!H23 -> Day 1 | G6: ==Dashboard!I23 -> TASK-FE-003 | H6: ==Dashboard!J23 -> Completed | I6: ==Dashboard!L23 -> Client RBAC guard integrated with token decoder
A7: ==Dashboard!A24 -> TASK-FE-005 | B7: ==Dashboard!C24 -> Axios Setup | C7: ==Dashboard!D24 -> Adithyan N | D7: ==Dashboard!E24 -> High | E7: ==Dashboard!F24 -> Completed | F7: ==Dashboard!H24 -> Day 1 | G7: ==Dashboard!I24 -> None | H7: ==Dashboard!J24 -> Completed | I7: ==Dashboard!L24 -> JWT interceptor setup, retry limits configured
A8: ==Dashboard!A25 -> TASK-FE-006 | B8: ==Dashboard!C25 -> Authentication UI | C8: ==Dashboard!D25 -> Adithyan N | D8: ==Dashboard!E25 -> High | E8: ==Dashboard!F25 -> Completed | F8: ==Dashboard!H25 -> Day 2 | G8: ==Dashboard!I25 -> TASK-FE-004 | H8: ==Dashboard!J25 -> Completed | I8: ==Dashboard!L25 -> Secure cookie setup and form validations active
A9: ==Dashboard!A26 -> TASK-FE-007 | B9: ==Dashboard!C26 -> Citizen Dashboard | C9: ==Dashboard!D26 -> Adithyan N | D9: ==Dashboard!E26 -> High | E9: ==Dashboard!F26 -> Completed | F9: ==Dashboard!H26 -> Day 2 | G9: ==Dashboard!I26 -> TASK-FE-004 | H9: ==Dashboard!J26 -> Completed | I9: ==Dashboard!L26 -> Overview console with responsive metrics cards active
A10: ==Dashboard!A27 -> TASK-FE-008 | B10: ==Dashboard!C27 -> Complaint UI | C10: ==Dashboard!D27 -> Adithyan N | D10: ==Dashboard!E27 -> High | E10: ==Dashboard!F27 -> In Progress | F10: ==Dashboard!H27 -> Day 3 | G10: ==Dashboard!I27 -> TASK-FE-007 | H10: ==Dashboard!J27 -> Pending | I10: ==Dashboard!L27 -> Input sanitizations in progress, UI layout complete
A11: ==Dashboard!A28 -> TASK-FE-009 | B11: ==Dashboard!C28 -> File Tracking UI | C11: ==Dashboard!D28 -> Adithyan N | D11: ==Dashboard!E28 -> Medium | E11: ==Dashboard!F28 -> In Progress | F11: ==Dashboard!H28 -> Day 3 | G11: ==Dashboard!I28 -> TASK-FE-005 | H11: ==Dashboard!J28 -> Pending | I11: ==Dashboard!L28 -> Timeline progress bar rendering in progress
A12: ==Dashboard!A29 -> TASK-FE-010 | B12: ==Dashboard!C29 -> Feedback UI | C12: ==Dashboard!D29 -> Adithyan N | D12: ==Dashboard!E29 -> Medium | E12: ==Dashboard!F29 -> Not Started | F12: ==Dashboard!H29 -> Day 5 | G12: ==Dashboard!I29 -> TASK-FE-008 | H12: ==Dashboard!J29 -> Pending | I12: ==Dashboard!L29 -> Satisfaction ratings form mockup completed
A13: ==Dashboard!A30 -> TASK-FE-011 | B13: ==Dashboard!C30 -> Staff Dashboard UI | C13: ==Dashboard!D30 -> Adithyan N | D13: ==Dashboard!E30 -> High | E13: ==Dashboard!F30 -> Not Started | F13: ==Dashboard!H30 -> Day 4 | G13: ==Dashboard!I30 -> TASK-FE-004 | H13: ==Dashboard!J30 -> Pending | I13: ==Dashboard!L30 -> Employee operations view blueprint set
A14: ==Dashboard!A31 -> TASK-FE-012 | B14: ==Dashboard!C31 -> Attendance UI | C14: ==Dashboard!D31 -> Adithyan N | D14: ==Dashboard!E31 -> High | E14: ==Dashboard!F31 -> Not Started | F14: ==Dashboard!H31 -> Day 4 | G14: ==Dashboard!I31 -> TASK-FE-011 | H14: ==Dashboard!J31 -> Pending | I14: ==Dashboard!L31 -> Liveness scan layout mock complete
... A20: ==Dashboard!A37 -> TASK-FE-018 | B20: ==Dashboard!C37 -> Final UI Testing | C20: ==Dashboard!D37 -> Adithyan N | D20: ==Dashboard!E37 -> High | E20: ==Dashboard!F37 -> Not Started | F20: ==Dashboard!H37 -> Day 7 | G20: ==Dashboard!I37 -> TASK-FE-017 | H20: ==Dashboard!J37 -> Pending | I20: ==Dashboard!L37 -> QA Visual signoff template configured

Sheet Database Tasks
A1: Database Tasks (Module Lead: Fathima Hana)
A2: Task ID | B2: Task Name | C2: Assigned To | D2: Priority | E2: Status | F2: Due Day | G2: Dependency | H2: Testing Status | I2: Remarks
A3: ==Dashboard!A49 -> TASK-DB-001 | B3: ==Dashboard!C49 -> Core Schema Creation | C3: ==Dashboard!D49 -> Fathima Hana | D3: ==Dashboard!E49 -> Critical | E3: ==Dashboard!F49 -> Completed | F3: ==Dashboard!H49 -> Sprint 0 | G3: ==Dashboard!I49 -> TASK-INF-001 | H3: ==Dashboard!J49 -> Completed | I3: ==Dashboard!L49 -> Support: Adithyan N. Constraints loaded and DB connection active
A4: ==Dashboard!A50 -> TASK-DB-002 | B4: ==Dashboard!C50 -> Mongoose Models | C4: ==Dashboard!D50 -> Fathima Hana | D4: ==Dashboard!E50 -> Critical | E4: ==Dashboard!F50 -> Completed | F4: ==Dashboard!H50 -> Day 1 | G4: ==Dashboard!I50 -> TASK-DB-001 | H4: ==Dashboard!J50 -> Completed | I4: ==Dashboard!L50 -> Support: Adithyan N. Unique key bounds and validators active
A5: ==Dashboard!A51 -> TASK-DB-003 | B5: ==Dashboard!C51 -> Relationships | C5: ==Dashboard!D51 -> Fathima Hana | D5: ==Dashboard!E51 -> High | E5: ==Dashboard!F51 -> Completed | F5: ==Dashboard!H51 -> Day 3 | G5: ==Dashboard!I51 -> TASK-DB-002 | H5: ==Dashboard!J51 -> Completed | I5: ==Dashboard!L51 -> Support: Adithyan N. Model referencing setup and verified
A6: ==Dashboard!A52 -> TASK-DB-004 | B6: ==Dashboard!C52 -> Indexing | C6: ==Dashboard!D52 -> Fathima Hana | D6: ==Dashboard!E52 -> Medium | E6: ==Dashboard!F52 -> Completed | F6: ==Dashboard!H52 -> Day 3 | G6: ==Dashboard!I52 -> TASK-DB-002 | H6: ==Dashboard!J52 -> Completed | I6: ==Dashboard!L52 -> Support: Adithyan N. Indexes configured, query execution fast
A7: ==Dashboard!A53 -> TASK-DB-005 | B7: ==Dashboard!C53 -> Validation | C7: ==Dashboard!D53 -> Fathima Hana | D7: ==Dashboard!E53 -> High | E7: ==Dashboard!F53 -> Not Started | F7: ==Dashboard!H53 -> Day 6 | G7: ==Dashboard!I53 -> TASK-DB-002 | H7: ==Dashboard!J53 -> Pending | I7: ==Dashboard!L53 -> Support: Adithyan N. Format checks drafted
A8: ==Dashboard!A54 -> TASK-DB-006 | B8: ==Dashboard!C54 -> Query Optimization | C8: ==Dashboard!D54 -> Fathima Hana | D8: ==Dashboard!E54 -> Medium | E8: ==Dashboard!F54 -> Not Started | F8: ==Dashboard!H54 -> Day 6 | G8: ==Dashboard!I54 -> TASK-DB-004 | H8: ==Dashboard!J54 -> Pending | I8: ==Dashboard!L54 -> Support: Adithyan N. Query optimization strategy defined

Sheet AI Tasks
A1: AI Tasks (Module Lead: Muhammed Sadik KT)
A2: Task ID | B2: Task Name | C2: Assigned To | D2: Priority | E2: Status | F2: Due Day | G2: Dependency | H2: Testing Status | I2: Remarks
A3: ==Dashboard!A55 -> TASK-AI-001 | B3: ==Dashboard!C55 -> Gemini Chatbot | C3: ==Dashboard!D55 -> Muhammed Sadik KT | D3: ==Dashboard!E55 -> High | E3: ==Dashboard!F55 -> Not Started | F3: ==Dashboard!H55 -> Day 5 | G3: ==Dashboard!I55 -> None | H3: ==Dashboard!J55 -> Pending | I3: ==Dashboard!L55 -> RAG context bounds applied
A4: ==Dashboard!A56 -> TASK-AI-002 | B4: ==Dashboard!C56 -> OCR | C4: ==Dashboard!D56 -> Muhammed Sadik KT | D4: ==Dashboard!E56 -> Medium | E4: ==Dashboard!F56 -> Not Started | F4: ==Dashboard!H56 -> Day 5 | G4: ==Dashboard!I56 -> None | H4: ==Dashboard!J56 -> Pending | I4: ==Dashboard!L56 -> Secure local storage sandbox specs
A5: ==Dashboard!A57 -> TASK-AI-003 | B5: ==Dashboard!C57 -> AI APIs | C5: ==Dashboard!D57 -> Muhammed Sadik KT | D5: ==Dashboard!E57 -> High | E5: ==Dashboard!F57 -> Not Started | F5: ==Dashboard!H57 -> Day 5 | G5: ==Dashboard!I57 -> None | H5: ==Dashboard!J57 -> Pending | I5: ==Dashboard!L57 -> Secure credentials configuration detailed
A6: ==Dashboard!A58 -> TASK-AI-004 | B6: ==Dashboard!C58 -> Prompt Engineering | C6: ==Dashboard!D58 -> Muhammed Sadik KT | D6: ==Dashboard!E58 -> Medium | E6: ==Dashboard!F58 -> Not Started | F6: ==Dashboard!H58 -> Day 5 | G6: ==Dashboard!I58 -> TASK-AI-001 | H6: ==Dashboard!J58 -> Pending | I6: ==Dashboard!L58 -> Prompt injection guards drafted
A7: ==Dashboard!A59 -> TASK-AI-005 | B7: ==Dashboard!C59 -> Face Recognition Core Implementation | C7: ==Dashboard!D59 -> Muhammed Sadik KT | D7: ==Dashboard!E59 -> Critical | E7: ==Dashboard!F59 -> Not Started | F7: ==Dashboard!H59 -> Day 4 | G7: ==Dashboard!I59 -> None | H7: ==Dashboard!J59 -> Pending | I7: ==Dashboard!L59 -> Volatile RAM comparison model designed

Sheet Face Recognition Tasks
A1: Face Recognition Tasks (Module Lead: Fadi Ahmed)
A2: Task ID | B2: Task Name | C2: Assigned To | D2: Priority | E2: Status | F2: Due Day | G2: Dependency | H2: Testing Status | I2: Remarks
A3: ==Dashboard!A60 -> TASK-FR-001 | B3: ==Dashboard!C60 -> Dataset Collection | C3: ==Dashboard!D60 -> Fadi Ahmed | D3: ==Dashboard!E60 -> Medium | E3: ==Dashboard!F60 -> Not Started | F3: ==Dashboard!H60 -> Day 4 | G3: ==Dashboard!I60 -> None | H3: ==Dashboard!J60 -> Pending | I3: ==Dashboard!L60 -> Offline template protection standards set
A4: ==Dashboard!A61 -> TASK-FR-002 | B4: ==Dashboard!C61 -> Prototype Refinement | C4: ==Dashboard!D61 -> Fadi Ahmed | D4: ==Dashboard!E61 -> High | E4: ==Dashboard!F61 -> Not Started | F4: ==Dashboard!H61 -> Day 4 | G4: ==Dashboard!I61 -> TASK-AI-005 | H4: ==Dashboard!J61 -> Pending | I4: ==Dashboard!L61 -> Anti-spoofing test frameworks ready
A5: ==Dashboard!A62 -> TASK-FR-003 | B5: ==Dashboard!C62 -> Camera Integration Testing | C5: ==Dashboard!D62 -> Fadi Ahmed | D5: ==Dashboard!E62 -> Medium | E5: ==Dashboard!F62 -> Not Started | F5: ==Dashboard!H62 -> Day 4 | G5: ==Dashboard!I62 -> None | H5: ==Dashboard!J62 -> Pending | I5: ==Dashboard!L62 -> Zero frame storage validation script written
A6: ==Dashboard!A63 -> TASK-FR-004 | B6: ==Dashboard!C63 -> Attendance Workflow Testing | C6: ==Dashboard!D63 -> Fadi Ahmed | D6: ==Dashboard!E63 -> High | E6: ==Dashboard!F63 -> Not Started | F6: ==Dashboard!H63 -> Day 5 | G6: ==Dashboard!I63 -> TASK-FR-003 | H6: ==Dashboard!J63 -> Pending | I6: ==Dashboard!L63 -> Consent constraints gating check template
A7: ==Dashboard!A64 -> TASK-FR-005 | B7: ==Dashboard!C64 -> Recognition Accuracy Testing | C7: ==Dashboard!D64 -> Fadi Ahmed | D7: ==Dashboard!E64 -> High | E7: ==Dashboard!F64 -> Not Started | F7: ==Dashboard!H64 -> Day 5 | G7: ==Dashboard!I64 -> TASK-FR-002 | H7: ==Dashboard!J64 -> Pending | I7: ==Dashboard!L64 -> Robustness audit report format ready
A8: ==Dashboard!A65 -> TASK-FR-006 | B8: ==Dashboard!C65 -> Cross-Browser Camera Testing | C8: ==Dashboard!D65 -> Fadi Ahmed | D8: ==Dashboard!E65 -> Medium | E8: ==Dashboard!F65 -> Not Started | F8: ==Dashboard!H65 -> Day 6 | G8: ==Dashboard!I65 -> TASK-FR-003 | H8: ==Dashboard!J65 -> Pending | I8: ==Dashboard!L65 -> Web permissions tests blueprint
A9: ==Dashboard!A66 -> TASK-FR-007 | B9: ==Dashboard!C66 -> System Integration Testing | C9: ==Dashboard!D66 -> Fadi Ahmed | D9: ==Dashboard!E66 -> High | E9: ==Dashboard!F66 -> Not Started | F9: ==Dashboard!H66 -> Day 6 | G9: ==Dashboard!I66 -> TASK-FR-004 | H9: ==Dashboard!J66 -> Pending | I9: ==Dashboard!L66 -> RBAC boundary check verified

Sheet Documentation & QA Tasks
A1: Documentation & QA Tasks (Module Lead: Minha Palakkathodi)
A2: Task ID | B2: Task Name | C2: Assigned To | D2: Priority | E2: Status | F2: Due Day | G2: Dependency | H2: Testing Status | I2: Remarks
A3: ==Dashboard!A67 -> TASK-QA-001 | B3: ==Dashboard!C67 -> Test Cases | C3: ==Dashboard!D67 -> Minha Palakkathodi | D3: ==Dashboard!E67 -> High | E3: ==Dashboard!F67 -> Completed | F3: ==Dashboard!H67 -> Day 2 | G3: ==Dashboard!I67 -> None | H3: ==Dashboard!J67 -> Completed | I3: ==Dashboard!L67 -> Validation schedules and manual test logs created
A4: ==Dashboard!A68 -> TASK-QA-002 | B4: ==Dashboard!C68 -> Traceability Matrix | C4: ==Dashboard!D68 -> Minha Palakkathodi | D4: ==Dashboard!E68 -> High | E4: ==Dashboard!F68 -> Completed | F4: ==Dashboard!H68 -> Day 1 | G4: ==Dashboard!I68 -> None | H4: ==Dashboard!J68 -> Completed | I4: ==Dashboard!L68 -> SRS mappings verified and formatted
A5: ==Dashboard!A69 -> TASK-QA-003 | B5: ==Dashboard!C69 -> QA Reports | C5: ==Dashboard!D69 -> Minha Palakkathodi | D5: ==Dashboard!E69 -> Medium | E5: ==Dashboard!F69 -> Not Started | F5: ==Dashboard!H69 -> Day 6 | G5: ==Dashboard!I69 -> None | H5: ==Dashboard!J69 -> Pending | I5: ==Dashboard!L69 -> Sprint review reports templates prepared
A6: ==Dashboard!A70 -> TASK-QA-004 | B6: ==Dashboard!C70 -> UAT | C6: ==Dashboard!D70 -> Minha Palakkathodi | D6: ==Dashboard!E70 -> High | E6: ==Dashboard!F70 -> Not Started | F6: ==Dashboard!H70 -> Day 7 | G6: ==Dashboard!I70 -> None | H6: ==Dashboard!J70 -> Pending | I6: ==Dashboard!L70 -> Acceptance signs template setup
A7: ==Dashboard!A71 -> TASK-QA-005 | B7: ==Dashboard!C71 -> Handover Documentation | C7: ==Dashboard!D71 -> Minha Palakkathodi | D7: ==Dashboard!E71 -> High | E7: ==Dashboard!F71 -> Not Started | F7: ==Dashboard!H71 -> Day 7 | G7: ==Dashboard!I71 -> None | H7: ==Dashboard!J71 -> Pending | I7: ==Dashboard!L71 -> Official handoff portfolio templates drafted
A8: ==Dashboard!A72 -> TASK-QA-006 | B8: ==Dashboard!C72 -> Documentation Updates | C8: ==Dashboard!D72 -> Minha Palakkathodi | D8: ==Dashboard!E72 -> Medium | E8: ==Dashboard!F72 -> Not Started | F8: ==Dashboard!H72 -> Day 7 | G8: ==Dashboard!I72 -> None | H8: ==Dashboard!J72 -> Pending | I8: ==Dashboard!L72 -> Final directory inventory check template

Sheet Infrastructure Tasks
A1: Infrastructure Tasks (Module Lead: Adithyan N + Muhammad Sanish)
A2: Task ID | B2: Task Name | C2: Assigned To | D2: Priority | E2: Status | F2: Due Day | G2: Dependency | H2: Testing Status | I2: Remarks
A3: ==Dashboard!A16 -> TASK-INF-001 | B3: ==Dashboard!C16 -> MongoDB Atlas Setup | C3: ==Dashboard!D16 -> Adithyan N | D3: ==Dashboard!E16 -> Critical | E3: ==Dashboard!F16 -> Completed | F3: ==Dashboard!H16 -> Sprint 0 | G3: ==Dashboard!I16 -> None | H3: ==Dashboard!J16 -> Completed | I3: ==Dashboard!L16 -> Admin controls configured and database connection verified
A4: ==Dashboard!A17 -> TASK-INF-002 | B4: ==Dashboard!C17 -> Environment Configuration | C4: ==Dashboard!D17 -> Muhammad Sanish | D4: ==Dashboard!E17 -> High | E4: ==Dashboard!F17 -> Completed | F4: ==Dashboard!H17 -> Sprint 0 | G4: ==Dashboard!I17 -> None | H4: ==Dashboard!J17 -> Completed | I4: ==Dashboard!L17 -> No secrets committed, configuration structure validated
