Workbook

Sheet Dashboard
A1: AI-Powered Smart Municipal Citizen Assistance & Staff Attendance Management System - Executive Dashboard
A2: Overall Completion % | C2: Blocked Tasks | E2: Critical Issues Open | G2: Open Bugs | I2: Security Checklist % | K2: Deployment Readiness % | M2: Demo Critical Tasks Remaining | O2: Open Security Issues | Q2: Testing Completion % | S2: Integration Completion %
A3: ==COUNTIF(F16:F111, "Completed")/COUNTA(A16:A111) -> 0 | C3: ==COUNTIF(F16:F111, "Blocked") -> 0 | E3: ==COUNTIFS(E16:E111, "Critical", F16:F111, "<>Completed") -> 7 | G3: ==COUNTIFS('Bug Tracker'!G3:G30, "<>Completed", 'Bug Tracker'!G3:G30, "<>") -> 5 | I3: ==COUNTIF('Security Checklist'!D3:D14, "Completed")/COUNTA('Security Checklist'!D3:D14) -> 0 | K3: ==COUNTIF('Deployment Checklist'!D3:D10, "Completed")/COUNTA('Deployment Checklist'!D3:D10) -> 0 | M3: ==COUNTIFS(F16:F111, "<>Completed", R16:R111, "Yes") -> 25 | O3: ==COUNTIFS('Security Review Tracker'!C3:C15, "<>Passed", 'Security Review Tracker'!C3:C15, "<>") -> 13 | Q3: ==COUNTIF('Testing Tracker'!F3:F12, "Passed")/COUNTA('Testing Tracker'!A3:A12) -> 0 | S3: ==COUNTIF('Integration Tracker'!F3:F12, "Completed")/COUNTA('Integration Tracker'!A3:A12) -> 0
A6: Team Workload & Progress Summary | H6: Module Development Status | O6: Day-Wise Progress Timeline
A7: Team Member | B7: Assigned Tasks | C7: Completed | D7: Pending | E7: Blocked | F7: Completion % | H7: Module Name | I7: Total Tasks | J7: Completed | K7: Pending | L7: Blocked | M7: Completion % | O7: Day | P7: Total Tasks | Q7: Completed | R7: Completion %
A8: Minha Palakkathodi | B8: ==COUNTIF($D$16:$D$111, A8) -> 9 | C8: ==COUNTIFS($D$16:$D$111, A8, $F$16:$F$111, "Completed") -> 0 | D8: ==B8-C8-E8 -> 9 | E8: ==COUNTIFS($D$16:$D$111, A8, $F$16:$F$111, "Blocked") -> 0 | F8: ==IF(B8>0, C8/B8, 0) -> 0 | H8: Backend | I8: ==COUNTIF($B$16:$B$111, H8) -> 20 | J8: ==COUNTIFS($B$16:$B$111, H8, $F$16:$F$111, "Completed") -> 0 | K8: ==I8-J8-L8 -> 20 | L8: ==COUNTIFS($B$16:$B$111, H8, $F$16:$F$111, "Blocked") -> 0 | M8: ==IF(I8>0, J8/I8, 0) -> 0 | O8: Sprint 0 | P8: ==COUNTIF($H$16:$H$111, O8) -> 7 | Q8: ==COUNTIFS($H$16:$H$111, O8, $F$16:$F$111, "Completed") -> 0 | R8: ==IF(P8>0, Q8/P8, 0) -> 0
A9: Adithyan N | B9: ==COUNTIF($D$16:$D$111, A9) -> 30 | C9: ==COUNTIFS($D$16:$D$111, A9, $F$16:$F$111, "Completed") -> 0 | D9: ==B9-C9-E9 -> 30 | E9: ==COUNTIFS($D$16:$D$111, A9, $F$16:$F$111, "Blocked") -> 0 | F9: ==IF(B9>0, C9/B9, 0) -> 0 | H9: Frontend | I9: ==COUNTIF($B$16:$B$111, H9) -> 24 | J9: ==COUNTIFS($B$16:$B$111, H9, $F$16:$F$111, "Completed") -> 0 | K9: ==I9-J9-L9 -> 24 | L9: ==COUNTIFS($B$16:$B$111, H9, $F$16:$F$111, "Blocked") -> 0 | M9: ==IF(I9>0, J9/I9, 0) -> 0 | O9: Day 1 | P9: ==COUNTIF($H$16:$H$111, O9) -> 28 | Q9: ==COUNTIFS($H$16:$H$111, O9, $F$16:$F$111, "Completed") -> 0 | R9: ==IF(P9>0, Q9/P9, 0) -> 0
A10: Fathima Hana | B10: ==COUNTIF($D$16:$D$111, A10) -> 16 | C10: ==COUNTIFS($D$16:$D$111, A10, $F$16:$F$111, "Completed") -> 0 | D10: ==B10-C10-E10 -> 16 | E10: ==COUNTIFS($D$16:$D$111, A10, $F$16:$F$111, "Blocked") -> 0 | F10: ==IF(B10>0, C10/B10, 0) -> 0 | H10: Database | I10: ==COUNTIF($B$16:$B$111, H10) -> 16 | J10: ==COUNTIFS($B$16:$B$111, H10, $F$16:$F$111, "Completed") -> 0 | K10: ==I10-J10-L10 -> 16 | L10: ==COUNTIFS($B$16:$B$111, H10, $F$16:$F$111, "Blocked") -> 0 | M10: ==IF(I10>0, J10/I10, 0) -> 0 | O10: Day 2 | P10: ==COUNTIF($H$16:$H$111, O10) -> 11 | Q10: ==COUNTIFS($H$16:$H$111, O10, $F$16:$F$111, "Completed") -> 0 | R10: ==IF(P10>0, Q10/P10, 0) -> 0
A11: Muhammad Sanish | B11: ==COUNTIF($D$16:$D$111, A11) -> 23 | C11: ==COUNTIFS($D$16:$D$111, A11, $F$16:$F$111, "Completed") -> 0 | D11: ==B11-C11-E11 -> 23 | E11: ==COUNTIFS($D$16:$D$111, A11, $F$16:$F$111, "Blocked") -> 0 | F11: ==IF(B11>0, C11/B11, 0) -> 0 | H11: AI | I11: ==COUNTIF($B$16:$B$111, H11) -> 9 | J11: ==COUNTIFS($B$16:$B$111, H11, $F$16:$F$111, "Completed") -> 0 | K11: ==I11-J11-L11 -> 9 | L11: ==COUNTIFS($B$16:$B$111, H11, $F$16:$F$111, "Blocked") -> 0 | M11: ==IF(I11>0, J11/I11, 0) -> 0 | O11: Day 3 | P11: ==COUNTIF($H$16:$H$111, O11) -> 6 | Q11: ==COUNTIFS($H$16:$H$111, O11, $F$16:$F$111, "Completed") -> 0 | R11: ==IF(P11>0, Q11/P11, 0) -> 0
A12: Fadi Ahmed | B12: ==COUNTIF($D$16:$D$111, A12) -> 9 | C12: ==COUNTIFS($D$16:$D$111, A12, $F$16:$F$111, "Completed") -> 0 | D12: ==B12-C12-E12 -> 9 | E12: ==COUNTIFS($D$16:$D$111, A12, $F$16:$F$111, "Blocked") -> 0 | F12: ==IF(B12>0, C12/B12, 0) -> 0 | H12: Face Recognition | I12: ==COUNTIF($B$16:$B$111, H12) -> 9 | J12: ==COUNTIFS($B$16:$B$111, H12, $F$16:$F$111, "Completed") -> 0 | K12: ==I12-J12-L12 -> 9 | L12: ==COUNTIFS($B$16:$B$111, H12, $F$16:$F$111, "Blocked") -> 0 | M12: ==IF(I12>0, J12/I12, 0) -> 0 | O12: Day 4 | P12: ==COUNTIF($H$16:$H$111, O12) -> 16 | Q12: ==COUNTIFS($H$16:$H$111, O12, $F$16:$F$111, "Completed") -> 0 | R12: ==IF(P12>0, Q12/P12, 0) -> 0
A13: Muhammed Sadik KT | B13: ==COUNTIF($D$16:$D$111, A13) -> 9 | C13: ==COUNTIFS($D$16:$D$111, A13, $F$16:$F$111, "Completed") -> 0 | D13: ==B13-C13-E13 -> 9 | E13: ==COUNTIFS($D$16:$D$111, A13, $F$16:$F$111, "Blocked") -> 0 | F13: ==IF(B13>0, C13/B13, 0) -> 0 | H13: Documentation & QA | I13: ==COUNTIF($B$16:$B$111, H13) -> 9 | J13: ==COUNTIFS($B$16:$B$111, H13, $F$16:$F$111, "Completed") -> 0 | K13: ==I13-J13-L13 -> 9 | L13: ==COUNTIFS($B$16:$B$111, H13, $F$16:$F$111, "Blocked") -> 0 | M13: ==IF(I13>0, J13/I13, 0) -> 0 | O13: Day 5 | P13: ==COUNTIF($H$16:$H$111, O13) -> 16 | Q13: ==COUNTIFS($H$16:$H$111, O13, $F$16:$F$111, "Completed") -> 0 | R13: ==IF(P13>0, Q13/P13, 0) -> 0
H14: Infrastructure | I14: ==COUNTIF($B$16:$B$111, H14) -> 9 | J14: ==COUNTIFS($B$16:$B$111, H14, $F$16:$F$111, "Completed") -> 0 | K14: ==I14-J14-L14 -> 9 | L14: ==COUNTIFS($B$16:$B$111, H14, $F$16:$F$111, "Blocked") -> 0 | M14: ==IF(I14>0, J14/I14, 0) -> 0 | O14: Day 6 | P14: ==COUNTIF($H$16:$H$111, O14) -> 6 | Q14: ==COUNTIFS($H$16:$H$111, O14, $F$16:$F$111, "Completed") -> 0 | R14: ==IF(P14>0, Q14/P14, 0) -> 0
A15: Task ID | B15: Module | C15: Task Name | D15: Assigned To | E15: Priority | F15: Status | G15: Progress % | H15: Due Day | I15: Dependency | J15: Deliverable | K15: Implementation Description | L15: Suggested Tech Stack | M15: Suggested Prompt Keywords | N15: Reference Documents | O15: Testing Status | P15: Security Status | Q15: Remarks | R15: Demo Critical?
A16: TASK-INF-001 | B16: Infrastructure | C16: Repository verification | D16: Adithyan N + Muhammad Sanish | E16: High | F16: Not Started | G16: ==IF(F16="Completed", 1, IF(F16="In Progress", 0.5, IF(F16="Review", 0.8, 0))) -> 0 | H16: Sprint 0 | I16: None | J16: Verified local Git repository and node workspace structures | K16: Verify and review the initial local Git repository layout and workspace structure. Check configuration files integrity like package.json, eslint configurations, and node workspaces setup. Ensure folder layout complies with project standards. Document structure errors and align branching structure before coding. | L16: Git, Node.js, Workspace CLI | M16: verify git layout, node workspace config, package.json check, folder integrity | N16: docs/02-System-Architecture/MASTER_ARCHITECTURE_v1.md | O16: Pending | P16: Pending | Q16: Check configuration files integrity | R16: No
A17: TASK-INF-002 | B17: Infrastructure | C17: Git workflow setup | D17: Adithyan N | E17: High | F17: Not Started | G17: ==IF(F17="Completed", 1, IF(F17="In Progress", 0.5, IF(F17="Review", 0.8, 0))) -> 0 | H17: Sprint 0 | I17: None | J17: Repository branching model and commit rules defined | K17: Define and establish standard repository branching guidelines and commit formats. Set up develop, main, and feature branch definitions on GitHub. Enforce pull request guidelines, commit tags (e.g. feat:, fix:), and merge criteria. Create a markdown documentation in docs detailing the repository rules. | L17: Git, GitHub, Markdown | M17: git workflow rules, branching strategy, pull request rules, commit guidelines | N17: docs/BRANCH_STRATEGY.md | O17: Pending | P17: Pending | Q17: Main/develop/feature branching rules | R17: No
A18: TASK-INF-003 | B18: Infrastructure | C18: Branch setup | D18: Adithyan N | E18: High | F18: Not Started | G18: ==IF(F18="Completed", 1, IF(F18="In Progress", 0.5, IF(F18="Review", 0.8, 0))) -> 0 | H18: Sprint 0 | I18: TASK-INF-002 | J18: Feature branches initialized on GitHub | K18: Initialize feature branches on the remote repository matching the project roadmap tasks list. Validate pull request pipelines and assign roles for code reviews. Set up status checks and branch protection rules for main and develop. Ensure developers can push feature branches without access conflicts. | L18: GitHub, Git CLI | M18: initialize feature branches, branch protection rules, code review assignments | N18: docs/BRANCH_STRATEGY.md | O18: Pending | P18: Pending | Q18: Initial pull request guidelines set | R18: No
A19: TASK-INF-004 | B19: Infrastructure | C19: MongoDB Atlas setup | D19: Adithyan N | E19: Critical | F19: Not Started | G19: ==IF(F19="Completed", 1, IF(F19="In Progress", 0.5, IF(F19="Review", 0.8, 0))) -> 0 | H19: Sprint 0 | I19: None | J19: Live MongoDB Atlas sandbox cluster initialized with access controls | K19: Set up a live MongoDB Atlas sandbox cluster with strict security controls. Create database users, manage credentials, and restrict network access with IP whitelist rules. Generate the production connection URI string. Validate database access locally using MongoDB Compass or terminal tools before deploying. | L19: MongoDB Atlas, MongoDB Compass, Network Security | M19: mongodb atlas setup, database clusters config, IP whitelists rules, connection string | N19: docs/04-Database-Architecture/SmartCity_DB_Architecture_v4.0_AI_Extension_Updated.md | O19: Pending | P19: Pending | Q19: IP whitelist rules configured | R19: No
A20: TASK-INF-005 | B20: Infrastructure | C20: Environment variables | D20: Muhammad Sanish | E20: High | F20: Not Started | G20: ==IF(F20="Completed", 1, IF(F20="In Progress", 0.5, IF(F20="Review", 0.8, 0))) -> 0 | H20: Sprint 0 | I20: None | J20: .env.example templates configuration sheets | K20: Create standard environment variables configuration templates (.env.example) for backend, frontend, and AI modules. Detail all required keys like DB connection strings, JWT secret keys, and Gemini API keys. Ensure no secret files are pushed to Git by verifying .gitignore excludes .env files. | L20: Node.js, Dotenv, Git Ignore | M20: dotenv configuration, environment template, gitignore rules, api keys templates | N20: docs/02-System-Architecture/MASTER_ARCHITECTURE_v1.md | O20: Pending | P20: Pending | Q20: No secrets checked in | R20: No
A21: TASK-INF-006 | B21: Infrastructure | C21: ESLint | D21: Adithyan N | E21: Medium | F21: Not Started | G21: ==IF(F21="Completed", 1, IF(F21="In Progress", 0.5, IF(F21="Review", 0.8, 0))) -> 0 | H21: Sprint 0 | I21: None | J21: ESLint standards rules deployed to repository root | K21: Deploy and configure standard ESLint code styling rules at the repository root. Establish code style limits for formatting, imports, and variables declaration to maintain code quality. Test styling standards compatibility in both backend and frontend workspaces. Create npm run lint check tasks. | L21: Node.js, ESLint, npm | M21: eslint config rules, code quality checks, linter automation scripts, code style configuration | N21: docs/02-System-Architecture/MASTER_ARCHITECTURE_v1.md | O21: Pending | P21: Pending | Q21: Static code styling checks active | R21: No
A22: TASK-INF-007 | B22: Infrastructure | C22: Prettier | D22: Adithyan N | E22: Medium | F22: Not Started | G22: ==IF(F22="Completed", 1, IF(F22="In Progress", 0.5, IF(F22="Review", 0.8, 0))) -> 0 | H22: Sprint 0 | I22: None | J22: Prettier formats scripts configured | K22: Integrate Prettier formatter scripts into the workspaces. Create the configuration rules files (.prettierrc) matching eslint specifications. Set up auto format on save configurations for Visual Studio Code or similar text editors. Validate formattings across backend, database, and client files. | L22: Prettier, ESLint, Editor SDK | M22: prettier configuration, code formatter scripts, editor styling setup, auto format guidelines | N22: docs/02-System-Architecture/MASTER_ARCHITECTURE_v1.md | O22: Pending | P22: Pending | Q22: Auto format on save verified | R22: No
A23: TASK-INF-008 | B23: Infrastructure | C23: Logging infrastructure | D23: Muhammad Sanish | E23: Medium | F23: Not Started | G23: ==IF(F23="Completed", 1, IF(F23="In Progress", 0.5, IF(F23="Review", 0.8, 0))) -> 0 | H23: Day 1 | I23: TASK-INF-005 | J23: Winston/Morgan logger system with data masking logic | K23: Deploy a centralized logging infrastructure using Winston and Morgan libraries. Design standard logging configurations to output info, warn, and error statements. Implement log transport mechanisms to files and console. Add critical data masking functions to redact sensitive client parameters or PII details. | L23: Node.js, Winston, Morgan, Regex | M23: winston logger config, morgan traffic logging, logger masking, PII redact logic | N23: docs/02-System-Architecture/MASTER_ARCHITECTURE_v1.md | O23: Pending | P23: Pending | Q23: PII credentials redact scripts applied | R23: No
A24: TASK-INF-009 | B24: Infrastructure | C24: Deployment preparation | D24: Adithyan N + Muhammad Sanish | E24: Medium | F24: Not Started | G24: ==IF(F24="Completed", 1, IF(F24="In Progress", 0.5, IF(F24="Review", 0.8, 0))) -> 0 | H24: Day 7 | I24: None | J24: Render/Vercel MVP launch readiness report | K24: Prepare the deployment pipelines and configuration documents for the MVP launch. Check hosting prerequisites for Render web services and Vercel client deployment. Generate CORS policy guidelines to prevent cross-origin errors in staging. Verify build dependencies and create the final launch report. | L24: Render, Vercel, CORS Configuration | M24: production deploy checklist, hosting environments config, CORS restrictions rules, launch plan | N24: docs/02-System-Architecture/MASTER_ARCHITECTURE_v1.md | O24: Pending | P24: Pending | Q24: Production CORS policies configured | R24: No
A25: TASK-DB-001 | B25: Database | C25: User schema | D25: Fathima Hana | E25: Critical | F25: Not Started | G25: ==IF(F25="Completed", 1, IF(F25="In Progress", 0.5, IF(F25="Review", 0.8, 0))) -> 0 | H25: Day 1 | I25: TASK-INF-004 | J25: Mongoose schema for users collection | K25: Create Mongoose schema definitions for users collection inside the backend models folder. Design fields for email, name, password hash, role reference, and active status. Add schema validations, unique index requirements, and automatic timestamps. Seed standard administrative credentials for testing. | L25: Node.js, MongoDB, Mongoose | M25: mongoose user schema, schema validations, user collection model, database index | N25: docs/04-Database-Architecture/SmartCity_DB_Architecture_v4.0_AI_Extension_Updated.md | O25: Pending | P25: Pending | Q25: Support: Adithyan N. Unique key bounds active | R25: No
A26: TASK-DB-002 | B26: Database | C26: Role schema | D26: Fathima Hana | E26: High | F26: Not Started | G26: ==IF(F26="Completed", 1, IF(F26="In Progress", 0.5, IF(F26="Review", 0.8, 0))) -> 0 | H26: Day 1 | I26: TASK-DB-001 | J26: Roles allocation definition mapping schemas | K26: Create Mongoose schema definitions for roles collection. Map role fields like role name (e.g. Citizen, Staff, Admin) and permission arrays references. Seed standard project role entries during database initialization. Implement strict integrity validations to prevent duplicate role registration. | L26: Node.js, MongoDB, Mongoose | M26: mongoose roles schema, role definitions map, database seeding, permissions index | N26: docs/04-Database-Architecture/SmartCity_DB_Architecture_v4.0_AI_Extension_Updated.md | O26: Pending | P26: Pending | Q26: Support: Adithyan N. Predefined roles seeded | R26: No
A27: TASK-DB-003 | B27: Database | C27: Permission schema | D27: Fathima Hana | E27: High | F27: Not Started | G27: ==IF(F27="Completed", 1, IF(F27="In Progress", 0.5, IF(F27="Review", 0.8, 0))) -> 0 | H27: Day 1 | I27: TASK-DB-002 | J27: Permissions collection schemas definition mapping routes | K27: Design and deploy Mongoose schema for the system permissions collection. Define attributes like resource path, CRUD actions flags, and permission descriptors. Map roles relationship arrays to permissions collections. Provide utility scripts to seed baseline route permission indices. | L27: Node.js, MongoDB, Mongoose | M27: mongoose permissions model, route permission check, database seeding scripts, RBAC config | N27: docs/04-Database-Architecture/SmartCity_DB_Architecture_v4.0_AI_Extension_Updated.md | O27: Pending | P27: Pending | Q27: Support: Adithyan N. RBAC maps | R27: No
... A111: TASK-QA-009 | B111: Documentation & QA | C111: Handover documentation | D111: Minha Palakkathodi | E111: High | F111: Not Started | G111: ==IF(F111="Completed", 1, IF(F111="In Progress", 0.5, IF(F111="Review", 0.8, 0))) -> 0 | H111: Day 7 | I111: TASK-QA-008 | J111: Municipality handover procedures manuals checklist | K111: Prepare the official municipality handoff procedures manuals. Detail roles credentials, system handover items logs, administration credentials rotation steps, and administrative contact channels guides sheets. | L111: Markdown, Handover Packages | M111: municipality handoff guide, credential keys rotation, administrator logins audit, handover manuals template | N111: docs/09-Handover-Documents/ARCHITECTURE_FREEZE_v1.md | O111: Pending | P111: Pending | Q111: Log logins and operational keys handover structures | R111: No

Sheet Kanban Board
A1: AI-Powered Smart Municipal Kanban Board (Status Flow Tracker)
B3: Project Name: | C3: Smart Municipal Assistance MVP | E3: Enterprise Lead: | F3: Adithyan N & PMO Team | H3: Target Milestone: | I3: 1-Week Rapid MVP Release
A5: Backlog / Future | D5: Not Started | G5: In Progress | J5: Under Review | M5: Completed
A6: Task ID | B6: Task Name | C6: Assigned To | D6: Task ID | E6: Task Name | F6: Assigned To | G6: Task ID | H6: Task Name | I6: Assigned To | J6: Task ID | K6: Task Name | L6: Assigned To | M6: Task ID | N6: Task Name | O6: Assigned To
D7: ==Dashboard!A16 -> TASK-INF-001 | E7: ==Dashboard!C16 -> Repository verification | F7: ==Dashboard!D16 -> Adithyan N + Muhammad Sanish
D8: ==Dashboard!A17 -> TASK-INF-002 | E8: ==Dashboard!C17 -> Git workflow setup | F8: ==Dashboard!D17 -> Adithyan N
D9: ==Dashboard!A18 -> TASK-INF-003 | E9: ==Dashboard!C18 -> Branch setup | F9: ==Dashboard!D18 -> Adithyan N
D10: ==Dashboard!A19 -> TASK-INF-004 | E10: ==Dashboard!C19 -> MongoDB Atlas setup | F10: ==Dashboard!D19 -> Adithyan N
D11: ==Dashboard!A20 -> TASK-INF-005 | E11: ==Dashboard!C20 -> Environment variables | F11: ==Dashboard!D20 -> Muhammad Sanish
D12: ==Dashboard!A21 -> TASK-INF-006 | E12: ==Dashboard!C21 -> ESLint | F12: ==Dashboard!D21 -> Adithyan N
D13: ==Dashboard!A22 -> TASK-INF-007 | E13: ==Dashboard!C22 -> Prettier | F13: ==Dashboard!D22 -> Adithyan N
D14: ==Dashboard!A23 -> TASK-INF-008 | E14: ==Dashboard!C23 -> Logging infrastructure | F14: ==Dashboard!D23 -> Muhammad Sanish
D15: ==Dashboard!A24 -> TASK-INF-009 | E15: ==Dashboard!C24 -> Deployment preparation | F15: ==Dashboard!D24 -> Adithyan N + Muhammad Sanish
D16: ==Dashboard!A25 -> TASK-DB-001 | E16: ==Dashboard!C25 -> User schema | F16: ==Dashboard!D25 -> Fathima Hana
D17: ==Dashboard!A26 -> TASK-DB-002 | E17: ==Dashboard!C26 -> Role schema | F17: ==Dashboard!D26 -> Fathima Hana
D18: ==Dashboard!A27 -> TASK-DB-003 | E18: ==Dashboard!C27 -> Permission schema | F18: ==Dashboard!D27 -> Fathima Hana
... D102: ==Dashboard!A111 -> TASK-QA-009 | E102: ==Dashboard!C111 -> Handover documentation | F102: ==Dashboard!D111 -> Minha Palakkathodi

Sheet Sprint 0
A1: Gantt Timeline Plan - Sprint 0 Schedule & Tasks
A2: Task ID | B2: Task Name | C2: Assigned To | D2: Priority | E2: Dependency | F2: Status | G2: Deliverable | H2: Implementation Description | I2: Suggested Tech Stack | J2: Suggested Prompt Keywords | K2: Reference Documents | L2: Testing Required | M2: Security Check Required | N2: Remarks
A3: ==Dashboard!A16 -> TASK-INF-001 | B3: ==Dashboard!C16 -> Repository verification | C3: ==Dashboard!D16 -> Adithyan N + Muhammad Sanish | D3: ==Dashboard!E16 -> High | E3: ==Dashboard!I16 -> None | F3: ==Dashboard!F16 -> Not Started | G3: Verified local Git repository and node workspace structures | H3: Verify and review the initial local Git repository layout and workspace structure. Check configuration files integrity like package.json, eslint configurations, and node workspaces setup. Ensure folder layout complies with project standards. Document structure errors and align branching structure before coding. | I3: Git, Node.js, Workspace CLI | J3: verify git layout, node workspace config, package.json check, folder integrity | K3: docs/02-System-Architecture/MASTER_ARCHITECTURE_v1.md | L3: Yes | M3: No | N3: ==Dashboard!Q16 -> Check configuration files integrity
A4: ==Dashboard!A17 -> TASK-INF-002 | B4: ==Dashboard!C17 -> Git workflow setup | C4: ==Dashboard!D17 -> Adithyan N | D4: ==Dashboard!E17 -> High | E4: ==Dashboard!I17 -> None | F4: ==Dashboard!F17 -> Not Started | G4: Repository branching model and commit rules defined | H4: Define and establish standard repository branching guidelines and commit formats. Set up develop, main, and feature branch definitions on GitHub. Enforce pull request guidelines, commit tags (e.g. feat:, fix:), and merge criteria. Create a markdown documentation in docs detailing the repository rules. | I4: Git, GitHub, Markdown | J4: git workflow rules, branching strategy, pull request rules, commit guidelines | K4: docs/BRANCH_STRATEGY.md | L4: No | M4: No | N4: ==Dashboard!Q17 -> Main/develop/feature branching rules
A5: ==Dashboard!A18 -> TASK-INF-003 | B5: ==Dashboard!C18 -> Branch setup | C5: ==Dashboard!D18 -> Adithyan N | D5: ==Dashboard!E18 -> High | E5: ==Dashboard!I18 -> TASK-INF-002 | F5: ==Dashboard!F18 -> Not Started | G5: Feature branches initialized on GitHub | H5: Initialize feature branches on the remote repository matching the project roadmap tasks list. Validate pull request pipelines and assign roles for code reviews. Set up status checks and branch protection rules for main and develop. Ensure developers can push feature branches without access conflicts. | I5: GitHub, Git CLI | J5: initialize feature branches, branch protection rules, code review assignments | K5: docs/BRANCH_STRATEGY.md | L5: No | M5: No | N5: ==Dashboard!Q18 -> Initial pull request guidelines set
A6: ==Dashboard!A19 -> TASK-INF-004 | B6: ==Dashboard!C19 -> MongoDB Atlas setup | C6: ==Dashboard!D19 -> Adithyan N | D6: ==Dashboard!E19 -> Critical | E6: ==Dashboard!I19 -> None | F6: ==Dashboard!F19 -> Not Started | G6: Live MongoDB Atlas sandbox cluster initialized with access controls | H6: Set up a live MongoDB Atlas sandbox cluster with strict security controls. Create database users, manage credentials, and restrict network access with IP whitelist rules. Generate the production connection URI string. Validate database access locally using MongoDB Compass or terminal tools before deploying. | I6: MongoDB Atlas, MongoDB Compass, Network Security | J6: mongodb atlas setup, database clusters config, IP whitelists rules, connection string | K6: docs/04-Database-Architecture/SmartCity_DB_Architecture_v4.0_AI_Extension_Updated.md | L6: Yes | M6: Yes | N6: ==Dashboard!Q19 -> IP whitelist rules configured
A7: ==Dashboard!A20 -> TASK-INF-005 | B7: ==Dashboard!C20 -> Environment variables | C7: ==Dashboard!D20 -> Muhammad Sanish | D7: ==Dashboard!E20 -> High | E7: ==Dashboard!I20 -> None | F7: ==Dashboard!F20 -> Not Started | G7: .env.example templates configuration sheets | H7: Create standard environment variables configuration templates (.env.example) for backend, frontend, and AI modules. Detail all required keys like DB connection strings, JWT secret keys, and Gemini API keys. Ensure no secret files are pushed to Git by verifying .gitignore excludes .env files. | I7: Node.js, Dotenv, Git Ignore | J7: dotenv configuration, environment template, gitignore rules, api keys templates | K7: docs/02-System-Architecture/MASTER_ARCHITECTURE_v1.md | L7: Yes | M7: Yes | N7: ==Dashboard!Q20 -> No secrets checked in
A8: ==Dashboard!A21 -> TASK-INF-006 | B8: ==Dashboard!C21 -> ESLint | C8: ==Dashboard!D21 -> Adithyan N | D8: ==Dashboard!E21 -> Medium | E8: ==Dashboard!I21 -> None | F8: ==Dashboard!F21 -> Not Started | G8: ESLint standards rules deployed to repository root | H8: Deploy and configure standard ESLint code styling rules at the repository root. Establish code style limits for formatting, imports, and variables declaration to maintain code quality. Test styling standards compatibility in both backend and frontend workspaces. Create npm run lint check tasks. | I8: Node.js, ESLint, npm | J8: eslint config rules, code quality checks, linter automation scripts, code style configuration | K8: docs/02-System-Architecture/MASTER_ARCHITECTURE_v1.md | L8: Yes | M8: No | N8: ==Dashboard!Q21 -> Static code styling checks active
A9: ==Dashboard!A22 -> TASK-INF-007 | B9: ==Dashboard!C22 -> Prettier | C9: ==Dashboard!D22 -> Adithyan N | D9: ==Dashboard!E22 -> Medium | E9: ==Dashboard!I22 -> None | F9: ==Dashboard!F22 -> Not Started | G9: Prettier formats scripts configured | H9: Integrate Prettier formatter scripts into the workspaces. Create the configuration rules files (.prettierrc) matching eslint specifications. Set up auto format on save configurations for Visual Studio Code or similar text editors. Validate formattings across backend, database, and client files. | I9: Prettier, ESLint, Editor SDK | J9: prettier configuration, code formatter scripts, editor styling setup, auto format guidelines | K9: docs/02-System-Architecture/MASTER_ARCHITECTURE_v1.md | L9: Yes | M9: No | N9: ==Dashboard!Q22 -> Auto format on save verified

Sheet Day 1
A1: Gantt Timeline Plan - Day 1 Schedule & Tasks
A2: Task ID | B2: Task Name | C2: Assigned To | D2: Priority | E2: Dependency | F2: Status | G2: Deliverable | H2: Implementation Description | I2: Suggested Tech Stack | J2: Suggested Prompt Keywords | K2: Reference Documents | L2: Testing Required | M2: Security Check Required | N2: Remarks
A3: ==Dashboard!A23 -> TASK-INF-008 | B3: ==Dashboard!C23 -> Logging infrastructure | C3: ==Dashboard!D23 -> Muhammad Sanish | D3: ==Dashboard!E23 -> Medium | E3: ==Dashboard!I23 -> TASK-INF-005 | F3: ==Dashboard!F23 -> Not Started | G3: Winston/Morgan logger system with data masking logic | H3: Deploy a centralized logging infrastructure using Winston and Morgan libraries. Design standard logging configurations to output info, warn, and error statements. Implement log transport mechanisms to files and console. Add critical data masking functions to redact sensitive client parameters or PII details. | I3: Node.js, Winston, Morgan, Regex | J3: winston logger config, morgan traffic logging, logger masking, PII redact logic | K3: docs/02-System-Architecture/MASTER_ARCHITECTURE_v1.md | L3: Yes | M3: Yes | N3: ==Dashboard!Q23 -> PII credentials redact scripts applied
A4: ==Dashboard!A25 -> TASK-DB-001 | B4: ==Dashboard!C25 -> User schema | C4: ==Dashboard!D25 -> Fathima Hana | D4: ==Dashboard!E25 -> Critical | E4: ==Dashboard!I25 -> TASK-INF-004 | F4: ==Dashboard!F25 -> Not Started | G4: Mongoose schema for users collection | H4: Create Mongoose schema definitions for users collection inside the backend models folder. Design fields for email, name, password hash, role reference, and active status. Add schema validations, unique index requirements, and automatic timestamps. Seed standard administrative credentials for testing. | I4: Node.js, MongoDB, Mongoose | J4: mongoose user schema, schema validations, user collection model, database index | K4: docs/04-Database-Architecture/SmartCity_DB_Architecture_v4.0_AI_Extension_Updated.md | L4: Yes | M4: Yes | N4: ==Dashboard!Q25 -> Support: Adithyan N. Unique key bounds active
A5: ==Dashboard!A26 -> TASK-DB-002 | B5: ==Dashboard!C26 -> Role schema | C5: ==Dashboard!D26 -> Fathima Hana | D5: ==Dashboard!E26 -> High | E5: ==Dashboard!I26 -> TASK-DB-001 | F5: ==Dashboard!F26 -> Not Started | G5: Roles allocation definition mapping schemas | H5: Create Mongoose schema definitions for roles collection. Map role fields like role name (e.g. Citizen, Staff, Admin) and permission arrays references. Seed standard project role entries during database initialization. Implement strict integrity validations to prevent duplicate role registration. | I5: Node.js, MongoDB, Mongoose | J5: mongoose roles schema, role definitions map, database seeding, permissions index | K5: docs/04-Database-Architecture/SmartCity_DB_Architecture_v4.0_AI_Extension_Updated.md | L5: Yes | M5: Yes | N5: ==Dashboard!Q26 -> Support: Adithyan N. Predefined roles seeded
A6: ==Dashboard!A27 -> TASK-DB-003 | B6: ==Dashboard!C27 -> Permission schema | C6: ==Dashboard!D27 -> Fathima Hana | D6: ==Dashboard!E27 -> High | E6: ==Dashboard!I27 -> TASK-DB-002 | F6: ==Dashboard!F27 -> Not Started | G6: Permissions collection schemas definition mapping routes | H6: Design and deploy Mongoose schema for the system permissions collection. Define attributes like resource path, CRUD actions flags, and permission descriptors. Map roles relationship arrays to permissions collections. Provide utility scripts to seed baseline route permission indices. | I6: Node.js, MongoDB, Mongoose | J6: mongoose permissions model, route permission check, database seeding scripts, RBAC config | K6: docs/04-Database-Architecture/SmartCity_DB_Architecture_v4.0_AI_Extension_Updated.md | L6: Yes | M6: Yes | N6: ==Dashboard!Q27 -> Support: Adithyan N. RBAC maps
A7: ==Dashboard!A28 -> TASK-DB-004 | B7: ==Dashboard!C28 -> Department schema | C7: ==Dashboard!D28 -> Fathima Hana | D7: ==Dashboard!E28 -> Medium | E7: ==Dashboard!I28 -> TASK-DB-001 | F7: ==Dashboard!F28 -> Not Started | G7: Department schemas mapping employees | H7: Create Mongoose schema mapping departments collection in the backend models directory. Add fields for department name, lead assigned reference, code, and active staff indices list. Implement Mongoose model validations and query middleware helper methods. Seed primary departments data. | I7: Node.js, MongoDB, Mongoose | J7: mongoose department schema, department metadata model, indexing strategy, data seed | K7: docs/04-Database-Architecture/SmartCity_DB_Architecture_v4.0_AI_Extension_Updated.md | L7: Yes | M7: No | N7: ==Dashboard!Q28 -> Support: Adithyan N. Collection indices
A8: ==Dashboard!A37 -> TASK-DB-013 | B8: ==Dashboard!C37 -> Indexes | C8: ==Dashboard!D37 -> Fathima Hana | D8: ==Dashboard!E37 -> High | E8: ==Dashboard!I37 -> TASK-DB-001 | F8: ==Dashboard!F37 -> Not Started | G8: Unique indices mapping user emails and tracking file ID keys | H8: Deploy custom database indexing rules on Mongoose schemas to optimize queries. Set unique compound indexes for user emails, tracking code IDs, and geospatial indexes for coordinates in complaints and attendance. Verify index coverage reports using mongo dashboard CLI tool. | I8: MongoDB, Mongoose Indexing CLI | J8: unique database indexes, geospatial coordinate indexing, explain query plans, database tuning | K8: docs/04-Database-Architecture/SmartCity_DB_Architecture_v4.0_AI_Extension_Updated.md | L8: Yes | M8: No | N8: ==Dashboard!Q37 -> Support: Adithyan N. Index strategies verified
A9: ==Dashboard!A38 -> TASK-DB-014 | B9: ==Dashboard!C38 -> Relationships | C9: ==Dashboard!D38 -> Fathima Hana | D9: ==Dashboard!E38 -> Medium | E9: ==Dashboard!I38 -> TASK-DB-002 | F9: ==Dashboard!F38 -> Not Started | G9: Foreign object reference bounds configuration in schemas | H9: Enforce Mongoose models relation controls and reference keys consistency check. Configure reference checks using pre-save validation hooks on employee ID references and complaint ID fields. Add custom error responses output when target foreign records are missing. | I9: Node.js, MongoDB, Mongoose Schema | J9: foreign key reference checks, schema validation rules, data relational consistency, database design | K9: docs/04-Database-Architecture/SmartCity_DB_Architecture_v4.0_AI_Extension_Updated.md | L9: Yes | M9: No | N9: ==Dashboard!Q38 -> Support: Adithyan N. Strict Mongoose validations
A10: ==Dashboard!A39 -> TASK-DB-015 | B10: ==Dashboard!C39 -> Validation rules | C10: ==Dashboard!D39 -> Fathima Hana | D10: ==Dashboard!E39 -> High | E10: ==Dashboard!I39 -> TASK-DB-001 | F10: ==Dashboard!F39 -> Not Started | G10: Mongoose validators evaluating text formats and coordinate bounds | H10: Write custom Mongoose validators evaluating data entry integrity. Add regex formats checks on mobile numbers, validation checks on email domains, and coordinates checks for municipal geographic bounds. Test validations triggers using model mock entries. | I10: Node.js, MongoDB, Mongoose Validator | J10: mongoose regex validators, geolocation coordinate validator, input sanity checker, error handler | K10: docs/04-Database-Architecture/SmartCity_DB_Architecture_v4.0_AI_Extension_Updated.md | L10: Yes | M10: Yes | N10: ==Dashboard!Q39 -> Support: Adithyan N. Input sanity checker
A11: ==Dashboard!A41 -> TASK-BE-001 | B11: ==Dashboard!C41 -> Express setup | C11: ==Dashboard!D41 -> Muhammad Sanish | D11: ==Dashboard!E41 -> Critical | E11: ==Dashboard!I41 -> TASK-INF-005 | F11: ==Dashboard!F41 -> Not Started | G11: Express server layout initialized with Helmet and CORS settings | H11: Scaffold and initialize Express.js web server inside the backend folder. Apply secure default middleware using Helmet, standard CORS origins controls rules, and JSON request parsers. Configure logs outputs and error handling hooks. Verify server responds successfully. | I11: Node.js, Express.js, Helmet, CORS | J11: express scaffold setup, helmet secure middleware, CORS restrictions setup, routing base config | K11: docs/05-API-Architecture/API_Architecture_DB_Aligned_v1.0.md | L11: Yes | M11: Yes | N11: ==Dashboard!Q41 -> Security middleware active
A12: ==Dashboard!A42 -> TASK-BE-002 | B12: ==Dashboard!C42 -> MongoDB connection | C12: ==Dashboard!D42 -> Muhammad Sanish | D12: ==Dashboard!E42 -> Critical | E12: ==Dashboard!I42 -> TASK-INF-004 | F12: ==Dashboard!F42 -> Not Started | G12: Mongoose database connector with auto-retry logics | H12: Code the Mongoose connection adapter script with auto-retry logics. Build robust error connection hooks reporting database disconnection, connection failure, or credential limits alerts. Establish connection pool size controls to limit database loads. | I12: Node.js, Mongoose, MongoDB Atlas | J12: mongoose connection adapter, auto reconnect loop, db credentials hook, collection pool size | K12: docs/05-API-Architecture/API_Architecture_DB_Aligned_v1.0.md | L12: Yes | M12: No | N12: ==Dashboard!Q42 -> Connection pool set to 10 connections max
A13: ==Dashboard!A43 -> TASK-BE-003 | B13: ==Dashboard!C43 -> Environment configuration | C13: ==Dashboard!D43 -> Muhammad Sanish | D13: ==Dashboard!E43 -> High | E13: ==Dashboard!I43 -> TASK-INF-005 | F13: ==Dashboard!F43 -> Not Started | G13: Dotenv loader checking and validating essential keys | H13: Write environment configuration loader module validating environment keys on startup. Verify the existence of required properties like MONGO_URI, JWT_SECRET, and PORT. Raise startup crash exceptions if mandatory keys are missing in the configuration. | I13: Node.js, Config Validation | J13: environment variable checks, schema parser config, error crash loop, bootstrap validation | K13: docs/05-API-Architecture/API_Architecture_DB_Aligned_v1.0.md | L13: Yes | M13: Yes | N13: ==Dashboard!Q43 -> Throws startup error on missing keys
A14: ==Dashboard!A48 -> TASK-BE-008 | B14: ==Dashboard!C48 -> RBAC middleware | C14: ==Dashboard!D48 -> Muhammad Sanish | D14: ==Dashboard!E48 -> Critical | E14: ==Dashboard!I48 -> TASK-BE-005 | F14: ==Dashboard!F48 -> Not Started | G14: Gated endpoint middleware evaluating token permissions | H14: Build role-based access control (RBAC) middleware gating backend API endpoints. Match user role from JWT validation payload against resource paths permissions registry. Block unauthorized queries with JSON format access denied errors (403 Status). | I14: Node.js, Express, RBAC Logic | J14: rbac validation middleware, endpoint permission check, resource authorization, jwt token mapping | K14: docs/05-API-Architecture/API_Architecture_DB_Aligned_v1.0.md | L14: Yes | M14: Yes | N14: ==Dashboard!Q48 -> Role sets validation checks
A15: ==Dashboard!A50 -> TASK-BE-010 | B15: ==Dashboard!C50 -> Error middleware | C15: ==Dashboard!D50 -> Muhammad Sanish | D15: ==Dashboard!E50 -> Medium | E15: ==Dashboard!I50 -> TASK-BE-001 | F15: ==Dashboard!F50 -> Not Started | G15: Centralized Express error handlers parsing exceptions | H15: Create centralized Express error processing middleware to catch runtime exceptions. Restructure errors outputting uniform JSON schemas containing custom messages and status codes. Mask inner diagnostics stack details on production environments. | I15: Node.js, Express Middleware | J15: express error middleware, centralized error formats, stack trace mask, custom exception mapper | K15: docs/05-API-Architecture/API_Architecture_DB_Aligned_v1.0.md | L15: Yes | M15: No | N15: ==Dashboard!Q50 -> Redacts stack traces in production environment
A16: ==Dashboard!A51 -> TASK-BE-011 | B16: ==Dashboard!C51 -> Validation middleware | C16: ==Dashboard!D51 -> Muhammad Sanish | D16: ==Dashboard!E51 -> High | E16: ==Dashboard!I51 -> TASK-BE-001 | F16: ==Dashboard!F51 -> Not Started | G16: Body/params query schemas validator middlewares | H16: Deploy payload format validation middleware using Express validation libraries (e.g. Joi, Zod). Build input schemas checking parameter data styles for logins, registrations, and complaints creation. Strip out unrecognized fields. | I16: Node.js, Express, Joi/Zod | J16: request body validation, request schema filters, middleware request parser, input filter | K16: docs/05-API-Architecture/API_Architecture_DB_Aligned_v1.0.md | L16: Yes | M16: Yes | N16: ==Dashboard!Q51 -> Strips unauthorized fields
A17: ==Dashboard!A58 -> TASK-BE-018 | B17: ==Dashboard!C58 -> Rate limiting | C17: ==Dashboard!D58 -> Muhammad Sanish | D17: ==Dashboard!E58 -> High | E17: ==Dashboard!I58 -> TASK-BE-001 | F17: ==Dashboard!F58 -> Not Started | G17: Rate-limiter setup restricting requests per IP window | H17: Apply rate limiting security middleware (e.g. express-rate-limit) on authentication and feedback API routes. Set maximum request thresholds within specific IP time frames to block database search brute force attempts. | I17: Node.js, Express, Express Rate Limit | J17: express rate limit, brute force protection, authentication route limit, api rate policy | K17: docs/05-API-Architecture/API_Architecture_DB_Aligned_v1.0.md | L17: Yes | M17: Yes | N17: ==Dashboard!Q58 -> Prevents brute force attempts
A18: ==Dashboard!A59 -> TASK-BE-019 | B18: ==Dashboard!C59 -> Health check API | C18: ==Dashboard!D59 -> Muhammad Sanish | D18: ==Dashboard!E59 -> Low | E18: ==Dashboard!I59 -> TASK-BE-001 | F18: ==Dashboard!F59 -> Not Started | G18: Diagnostics route returning system status | H18: Write system diagnostic health check route. Create endpoint returning status checks details for active MongoDB connectivity, memory limits details, and uptime metric logs. Mask system paths from unauthorized requests. | I18: Node.js, Express, System CLI | J18: health check endpoint, mongoose database validation, system metrics logs, diagnostics route | K18: docs/05-API-Architecture/API_Architecture_DB_Aligned_v1.0.md | L18: Yes | M18: No | N18: ==Dashboard!Q59 -> Returns DB status and memory limits details
A19: ==Dashboard!A61 -> TASK-FE-001 | B19: ==Dashboard!C61 -> React project setup | C19: ==Dashboard!D61 -> Adithyan N | D19: ==Dashboard!E61 -> High | E19: ==Dashboard!I61 -> None | F19: ==Dashboard!F61 -> Not Started | G19: Vite React scaffold template created | H19: Scaffold React frontend workspace template using Vite build tool. Establish dependency packages list containing Axios, React Router, TailwindCSS, and ESLint configs. Validate dev server initializes cleanly and page builds error-free. | I19: Node.js, Vite, React, npm | J19: vite react setup, frontend workspace config, client dependency install, build setup | K19: docs/06-UI-Architecture/Frontend_Architecture_Final_Merged_Updated.pdf | L19: Yes | M19: No | N19: ==Dashboard!Q61 -> Project workspace initialized
A20: ==Dashboard!A62 -> TASK-FE-002 | B20: ==Dashboard!C62 -> Tailwind setup | C20: ==Dashboard!D62 -> Adithyan N | D20: ==Dashboard!E62 -> High | E20: ==Dashboard!I62 -> TASK-FE-001 | F20: ==Dashboard!F62 -> Not Started | G20: Tailwind utility framework config initialized | H20: Install and configure TailwindCSS framework inside client workspace. Configure custom project theme parameters including HSL color palette mappings, fonts, and responsive grid values in tailwind.config.js. Test styling inputs. | I20: TailwindCSS, PostCSS, Autoprefixer | J20: tailwindcss client setup, custom color layouts, theme palette map, stylesheet utility | K20: docs/06-UI-Architecture/Frontend_Architecture_Final_Merged_Updated.pdf | L20: Yes | M20: No | N20: ==Dashboard!Q62 -> Custom theme color palettes mapped
A21: ==Dashboard!A63 -> TASK-FE-003 | B21: ==Dashboard!C63 -> Folder structure | C21: ==Dashboard!D63 -> Adithyan N | D21: ==Dashboard!E63 -> Medium | E21: ==Dashboard!I63 -> TASK-FE-001 | F21: ==Dashboard!F63 -> Not Started | G21: Standard client pages/components directory structured | H21: Organize folder structure layout for frontend modules. Set up pages, components, assets, contexts, hooks, services, and utils subfolders inside src folder. Deploy file organization criteria guidelines file for developer teams. | I21: Vite, React Workspace | J21: folder architecture layout, files layout organization, clean code pattern, modular structure | K21: docs/06-UI-Architecture/Frontend_Architecture_Final_Merged_Updated.pdf | L21: No | M21: No | N21: ==Dashboard!Q63 -> Standard clean coding layout
A22: ==Dashboard!A64 -> TASK-FE-004 | B22: ==Dashboard!C64 -> Global layout | C22: ==Dashboard!D64 -> Adithyan N | D22: ==Dashboard!E64 -> High | E22: ==Dashboard!I64 -> TASK-FE-003 | F22: ==Dashboard!F64 -> Not Started | G22: Responsive sidebars and navigation headers layouts | H22: Build global application layout components including responsive sidebars, main navigation headers, and content containers. Ensure menus collapse on mobile viewports. Integrate user profile card previews and notifications indicator buttons. | I22: React, TailwindCSS, Heroicons | J22: global sidebar component, header navbar layouts, mobile drawer controls, desktop layout shell | K22: docs/06-UI-Architecture/Frontend_Architecture_Final_Merged_Updated.pdf | L22: Yes | M22: No | N22: ==Dashboard!Q64 -> Mobile responsive shell layout
A23: ==Dashboard!A65 -> TASK-FE-005 | B23: ==Dashboard!C65 -> Routing | C23: ==Dashboard!D65 -> Adithyan N | D23: ==Dashboard!E65 -> High | E23: ==Dashboard!I65 -> TASK-FE-001 | F23: ==Dashboard!F65 -> Not Started | G23: React Router paths configuration mapping | H23: Integrate React Router library setup. Define paths mappings for public citizen homepages, auth views, dashboards, complaints management panels, tracking search views, and settings. Build fallback routes catching unmatched paths. | I23: React, React Router DOM | J23: react router client, path route definitions, route routing manager, browser paths map | K23: docs/06-UI-Architecture/Frontend_Architecture_Final_Merged_Updated.pdf | L23: Yes | M23: No | N23: ==Dashboard!Q65 -> URL router structure finalized
A24: ==Dashboard!A66 -> TASK-FE-006 | B24: ==Dashboard!C66 -> Protected routes | C24: ==Dashboard!D66 -> Adithyan N | D24: ==Dashboard!E66 -> High | E24: ==Dashboard!I66 -> TASK-FE-005 | F24: ==Dashboard!F66 -> Not Started | G24: Route wrapper gating views based on user login token | H24: Create reusable React route guard components that prevent unauthorized users from accessing protected pages. Verify JWT token validity and user roles before rendering pages. Redirect unauthenticated users to the login page and unauthorized users to an access denied page. Integrate with React Router and centralized authentication context/store. Test by attempting direct URL access to restricted routes. | I24: React, React Router, Context API | J24: client route guard, role check component, guest redirect route, route permission gate | K24: docs/06-UI-Architecture/Frontend_Architecture_Final_Merged_Updated.pdf | L24: Yes | M24: Yes | N24: ==Dashboard!Q66 -> Redirects guest to login page
A25: ==Dashboard!A67 -> TASK-FE-007 | B25: ==Dashboard!C67 -> Axios client | C25: ==Dashboard!D67 -> Adithyan N | D25: ==Dashboard!E67 -> High | E25: ==Dashboard!I67 -> None | F25: ==Dashboard!F67 -> Not Started | G25: Custom Axios client class initialized | H25: Develop Axios API client service setup. Configure base URL matching backend gateway, timeout limits, and default request headers definitions. Include error processing logic capturing standard network errors or request cancellations. | I25: Node.js, Axios Client, Express API | J25: axios client config, api routing base, endpoint timeout handler, network connection check | K25: docs/06-UI-Architecture/Frontend_Architecture_Final_Merged_Updated.pdf | L25: Yes | M25: No | N25: ==Dashboard!Q67 -> Base configuration templates
A26: ==Dashboard!A68 -> TASK-FE-008 | B26: ==Dashboard!C68 -> API interceptors | C26: ==Dashboard!D68 -> Adithyan N | D26: ==Dashboard!E68 -> High | E26: ==Dashboard!I68 -> TASK-FE-007 | F26: ==Dashboard!F68 -> Not Started | G26: JWT token injection request/response interceptors | H26: Implement Axios interceptors injecting JWT validation credentials automatically. Write response interceptors monitoring 401 Unauthorized codes to trigger token refresh sequences or clean up local storage caches and force login views. | I26: Node.js, Axios Interceptors, JWT Token | J26: jwt request interceptor, token refresh hooks, axios token injector, unauthorized handler | K26: docs/06-UI-Architecture/Frontend_Architecture_Final_Merged_Updated.pdf | L26: Yes | M26: Yes | N26: ==Dashboard!Q68 -> Auto attaches auth tokens to headers
A27: ==Dashboard!A79 -> TASK-FE-019 | B27: ==Dashboard!C79 -> Reusable Components | C27: ==Dashboard!D79 -> Adithyan N | D27: ==Dashboard!E79 -> Medium | E27: ==Dashboard!I79 -> TASK-FE-002 | F27: ==Dashboard!F79 -> Not Started | G27: Standard buttons, forms input fields, modal dialogs library | H27: Write reusable UI components components library. Construct unified designs for inputs, custom buttons, modal dialog containers, loader spinners, feedback alert boxes, and dropdown select fields, matching styling criteria. | I27: React, TailwindCSS, Modular CSS | J27: reusable input components, customized button designs, modal popup wrapper, common asset styles | K27: docs/06-UI-Architecture/Frontend_Architecture_Final_Merged_Updated.pdf | L27: Yes | M27: No | N27: ==Dashboard!Q79 -> Common component assets
A28: ==Dashboard!A82 -> TASK-FE-022 | B28: ==Dashboard!C82 -> Error boundaries | C28: ==Dashboard!D82 -> Adithyan N | D28: ==Dashboard!E82 -> Low | E28: ==Dashboard!I82 -> TASK-FE-001 | F28: ==Dashboard!F82 -> Not Started | G28: React fallback boundaries catching rendering errors | H28: Write custom React error boundary wrappers capturing rendering exceptions. Prevent app crash locks by displaying clean recovery warnings templates. Exclude core developer debug logs stack details from user-facing screens. | I28: React Component SDK | J28: react error boundary, react rendering recovery, application fallback layout, crash warning screens | K28: docs/06-UI-Architecture/Frontend_Architecture_Final_Merged_Updated.pdf | L28: Yes | M28: No | N28: ==Dashboard!Q82 -> No stack details shown in production UI
A29: ==Dashboard!A83 -> TASK-FE-023 | B29: ==Dashboard!C83 -> Loading components | C29: ==Dashboard!D83 -> Adithyan N | D29: ==Dashboard!E83 -> Low | E29: ==Dashboard!I83 -> TASK-FE-001 | F29: ==Dashboard!F83 -> Not Started | G29: Standardized skeleton loader elements | H29: Build visual skeleton loader components mimicking page layouts during loading events. Design loading indicators representing statistics lists, text blocks, table rows, and dashboard blocks to improve perceived speeds. | I29: React, TailwindCSS, Shimmer Animation | J29: skeleton card loaders, page loading layout, shimmer CSS animations, data fetching wrapper | K29: docs/06-UI-Architecture/Frontend_Architecture_Final_Merged_Updated.pdf | L29: Yes | M29: No | N29: ==Dashboard!Q83 -> Visual placeholders setup
A30: ==Dashboard!A103 -> TASK-QA-001 | B30: ==Dashboard!C103 -> Requirement traceability | C30: ==Dashboard!D103 -> Minha Palakkathodi | D30: ==Dashboard!E103 -> High | E30: ==Dashboard!I103 -> None | F30: ==Dashboard!F103 -> Not Started | G30: RTM spreadsheet linking requirements to components code | H30: Develop the Requirement Traceability Matrix (RTM) document. Map SRS features targets to database schemas layouts, api route controllers, and frontend pages. Verify complete specification coverage in active worksheets. | I30: Markdown, Excel Workspace | J30: rtm document structure, srs traceability mapping, specification validation index, quality metrics | K30: docs/01-SRS/SRS_AI_Powered_Municipality_Management_Portal_Updated.docx | L30: No | M30: No | N30: ==Dashboard!Q103 -> Traceability index setup

Sheet Day 2
A1: Gantt Timeline Plan - Day 2 Schedule & Tasks
A2: Task ID | B2: Task Name | C2: Assigned To | D2: Priority | E2: Dependency | F2: Status | G2: Deliverable | H2: Implementation Description | I2: Suggested Tech Stack | J2: Suggested Prompt Keywords | K2: Reference Documents | L2: Testing Required | M2: Security Check Required | N2: Remarks
A3: ==Dashboard!A29 -> TASK-DB-005 | B3: ==Dashboard!C29 -> Complaint schema | C3: ==Dashboard!D29 -> Fathima Hana | D3: ==Dashboard!E29 -> Critical | E3: ==Dashboard!I29 -> TASK-DB-001 | F3: ==Dashboard!F29 -> Not Started | G3: Complaints database models with status trackers | H3: Develop the complaints Mongoose database model. Define keys for tracking category, description text, citizen creator reference, current status (e.g. Open, In Progress, Resolved), coordinates, and file attachments URI strings. Enforce strict Mongoose input validators for data fields. | I3: Node.js, MongoDB, Mongoose | J3: mongoose complaint schema, geolocation parameters, image path string, input validations | K3: docs/04-Database-Architecture/SmartCity_DB_Architecture_v4.0_AI_Extension_Updated.md | L3: Yes | M3: Yes | N3: ==Dashboard!Q29 -> Support: Adithyan N. Handles attachments path strings
A4: ==Dashboard!A30 -> TASK-DB-006 | B4: ==Dashboard!C30 -> Complaint assignment schema | C4: ==Dashboard!D30 -> Fathima Hana | D4: ==Dashboard!E30 -> High | E4: ==Dashboard!I30 -> TASK-DB-005 | F4: ==Dashboard!F30 -> Not Started | G4: Assignments tracking schemas mapping assignees and times | H4: Create Mongoose schema tracking complaints assignments history. Add attributes for complaint ID reference, assigned employee reference, manager dispatcher reference, assign date, and status tags. Add pre-save validations confirming target assignee is a valid staff user. | I4: Node.js, MongoDB, Mongoose | J4: mongoose assignment schema, staff reference checking, ticket lifecycle tracker, validation rule | K4: docs/04-Database-Architecture/SmartCity_DB_Architecture_v4.0_AI_Extension_Updated.md | L4: Yes | M4: No | N4: ==Dashboard!Q30 -> Support: Adithyan N. References user and complaint
A5: ==Dashboard!A44 -> TASK-BE-004 | B5: ==Dashboard!C44 -> Authentication APIs | C5: ==Dashboard!D44 -> Muhammad Sanish | D5: ==Dashboard!E44 -> Critical | E5: ==Dashboard!I44 -> TASK-BE-001 | F5: ==Dashboard!F44 -> Not Started | G5: Login and signup backend API router endpoints | H5: Build secure authentication APIs for user registration and user login in Express.js. Retrieve payload fields, execute validations check, and hash passwords using bcrypt algorithm (rounds >= 10). Return success or structured failure code payload. | I5: Node.js, Express, Bcrypt | J5: user registration api, express login route, bcrypt hashing config, user models lookup | K5: docs/05-API-Architecture/API_Architecture_DB_Aligned_v1.0.md | L5: Yes | M5: Yes | N5: ==Dashboard!Q44 -> Bcrypt salt rounds configured
A6: ==Dashboard!A45 -> TASK-BE-005 | B6: ==Dashboard!C45 -> JWT implementation | C6: ==Dashboard!D45 -> Muhammad Sanish | D6: ==Dashboard!E45 -> Critical | E6: ==Dashboard!I45 -> TASK-BE-004 | F6: ==Dashboard!F45 -> Not Started | G6: Access token issuance logic mapped to JWT key payload | H6: Implement JWT token creation logic on successful logins. Generate signature payloads containing user ID, role, name, and department reference details. Define short access token expiration limits (e.g. 15 mins). Set up token verification helper middleware. | I6: Node.js, Express, JWT | J6: jwt signature token, token payload mapping, token expiry check, signature validation | K6: docs/05-API-Architecture/API_Architecture_DB_Aligned_v1.0.md | L6: Yes | M6: Yes | N6: ==Dashboard!Q45 -> Token expires in 15 mins
A7: ==Dashboard!A46 -> TASK-BE-006 | B7: ==Dashboard!C46 -> Refresh token API | C7: ==Dashboard!D46 -> Muhammad Sanish | D7: ==Dashboard!E46 -> High | E7: ==Dashboard!I46 -> TASK-BE-005 | F7: ==Dashboard!F46 -> Not Started | G7: Rotating refresh token endpoints validations | H7: Create secure refresh token APIs supporting token rotation schemes. Maintain active refresh tokens in a cookie transport with HTTPOnly, Secure, and SameSite tags. Verify token validation and rotate credentials on access token renewal requests. | I7: Node.js, Express, JWT, Cookie Parser | J7: refresh token api, secure cookie transport, token rotation logic, session refresh route | K7: docs/05-API-Architecture/API_Architecture_DB_Aligned_v1.0.md | L7: Yes | M7: Yes | N7: ==Dashboard!Q46 -> Secure cookie transport tags configuration
A8: ==Dashboard!A47 -> TASK-BE-007 | B8: ==Dashboard!C47 -> Logout API | C8: ==Dashboard!D47 -> Muhammad Sanish | D8: ==Dashboard!E47 -> Medium | E8: ==Dashboard!I47 -> TASK-BE-005 | F8: ==Dashboard!F47 -> Not Started | G8: Token cleanup and session revocation middleware endpoints | H8: Write session logout controller revoke endpoint. Remove client refresh token credentials, delete session tracking documents, and clear token transport cookie fields. Confirm user cannot refresh validation tokens after logging out. | I8: Node.js, Express, Cookie Manager | J8: logout controller api, token cookie clearing, session delete route, express cookie clear | K8: docs/05-API-Architecture/API_Architecture_DB_Aligned_v1.0.md | L8: Yes | M8: No | N8: ==Dashboard!Q47 -> Revokes active refresh session
A9: ==Dashboard!A52 -> TASK-BE-012 | B9: ==Dashboard!C52 -> Complaint APIs | C9: ==Dashboard!D52 -> Muhammad Sanish | D9: ==Dashboard!E52 -> High | E9: ==Dashboard!I52 -> TASK-BE-008 | F9: ==Dashboard!F52 -> Not Started | G9: Create, update, assign, and query complaints APIs | H9: Build grievance complaint CRUD endpoints. Code controllers validating citizen login context, storing geographic coordinates, attachment references, and routing ticket assign processes. Enforce resource ownership checks during update operations. | I9: Node.js, Express, Mongoose | J9: complaint endpoints crud, coordinates geo parsing, file upload paths, updates validation | K9: docs/05-API-Architecture/API_Architecture_DB_Aligned_v1.0.md | L9: Yes | M9: Yes | N9: ==Dashboard!Q52 -> Resource ownership validations active
A10: ==Dashboard!A69 -> TASK-FE-009 | B10: ==Dashboard!C69 -> Authentication pages | C10: ==Dashboard!D69 -> Adithyan N | D10: ==Dashboard!E69 -> High | E10: ==Dashboard!I69 -> TASK-FE-006 | F10: ==Dashboard!F69 -> Not Started | G10: Responsive Login and registration forms UI layouts | H10: Create responsive login and citizen registration form interfaces. Integrate client-side formatting checks for passwords strength, mobile numbers regex structures, and email formats. Validate error feedback alerts display on validation failures. | I10: React, TailwindCSS, Form State | J10: login layout ui, citizen registration form, input validation bounds, input error displays | K10: docs/06-UI-Architecture/Frontend_Architecture_Final_Merged_Updated.pdf | L10: Yes | M10: Yes | N10: ==Dashboard!Q69 -> Client side input validation rules active
A11: ==Dashboard!A70 -> TASK-FE-010 | B11: ==Dashboard!C70 -> Citizen Dashboard | C11: ==Dashboard!D70 -> Adithyan N | D11: ==Dashboard!E70 -> High | E11: ==Dashboard!I70 -> TASK-FE-006 | F11: ==Dashboard!F70 -> Not Started | G11: Grievance list overview panel and stats widgets UI | H11: Develop the main Citizen Dashboard panel view. Design summary statistics widgets showcasing total complaints logged, active tickets count, and completed complaints. Include filter selectors filtering complaints list details. | I11: React, TailwindCSS, Lucide Icons | J11: citizen portal interface, dashboard tracking view, tickets status table, citizen statistics widgets | K11: docs/06-UI-Architecture/Frontend_Architecture_Final_Merged_Updated.pdf | L11: Yes | M11: No | N11: ==Dashboard!Q70 -> Overview dashboard for citizen portals
A12: ==Dashboard!A71 -> TASK-FE-011 | B12: ==Dashboard!C71 -> Complaint Management UI | C12: ==Dashboard!D71 -> Adithyan N | D12: ==Dashboard!E71 -> High | E12: ==Dashboard!I71 -> TASK-FE-010 | F12: ==Dashboard!F71 -> Not Started | G12: Complaint intake form components with file attachment uploaders | H12: Build complaint intake form dashboard view. Support file attachments uploads, geographic coordinates input using maps plugins or geolocation browsers, category select input, and description text fields. Validate constraints checks. | I12: React, TailwindCSS, Geolocation API | J12: complaint submission layout, file attach validation, coordinates browser picker, form submittals | K12: docs/06-UI-Architecture/Frontend_Architecture_Final_Merged_Updated.pdf | L12: Yes | M12: Yes | N12: ==Dashboard!Q71 -> File type constraints validated
A13: ==Dashboard!A104 -> TASK-QA-002 | B13: ==Dashboard!C104 -> Test case creation | C13: ==Dashboard!D104 -> Minha Palakkathodi | D13: ==Dashboard!E104 -> High | E13: ==Dashboard!I104 -> TASK-QA-001 | F13: ==Dashboard!F104 -> Not Started | G13: Functional test cases suite covering citizen/staff actions | H13: Write manual testing scripts covering citizen registrations, complaints logging lifecycle, file tracking number search queries, and biometric attendance logs. Detail expected results formats for testers. | I13: Markdown, QA Test Sheets | J13: manual test script, user action validations, expected results table, test case layout | K13: docs/01-SRS/SRS_AI_Powered_Municipality_Management_Portal_Updated.docx | L13: No | M13: No | N13: ==Dashboard!Q104 -> Manual check sheets ready

Sheet Day 3
A1: Gantt Timeline Plan - Day 3 Schedule & Tasks
A2: Task ID | B2: Task Name | C2: Assigned To | D2: Priority | E2: Dependency | F2: Status | G2: Deliverable | H2: Implementation Description | I2: Suggested Tech Stack | J2: Suggested Prompt Keywords | K2: Reference Documents | L2: Testing Required | M2: Security Check Required | N2: Remarks
